Workbook
Name ListaEquipamentos: Equipamentos!$A$6:$A$13
Name ListaMotivos: 'Motivos de Parada'!$A$7:$A$26

Sheet Equipamentos
A1: CADASTRO DE EQUIPAMENTOS
A3: FS QUERÊNCIA - MT
A5: Equipamento | B5: Placa / Identificação | C5: Observações
A6: Guindaste 30 t | B6: ABC-1234
A7: Guindaste 70 t | B7: DEF-5678
A8: Caminhão Munck | B8: GHI-9012

Sheet Motivos de Parada
A4: MOTIVOS DE PARADA
A5: FS - QUERÊNCIA
A6: Motivo
A7: Manutenção
A8: Vazamento de óleo
A9: Abastecimento
A10: Sem operador
A11: Aguardando cliente / liberação
A12: Falta de frente de serviço
A13: Chuva / condições climáticas
A14: Deslocamento / mobilização
A15: Outros

Sheet Lançamentos Diários
C1: CONTROLE DIÁRIO DE HORAS — GUINDASTES E MUNCK
A4: Data | B4: Equipamento | C4: Operador | D4: Cliente / Obra | E4: Hora início | F4: Hora término | G4: Intervalo almoço (h:mm) | H4: Horímetro inicial | I4: Horímetro final | J4: Horas totais | K4: Horas paradas | L4: Horas efetivas trabalhadas | M4: Nº de paradas | N4: Horas horímetro | O4: Observações
A5: 46266 | B5: Guindaste 30 t | C5: João Silva | D5: Obra Centro — Construtora X | E5: 0.29166667 | F5: 0.70833333 | G5: 0.041666667 | H5: 1250 | I5: 1256.5 | J5: =IF(OR(E5="",F5=""),"",ROUND((MOD(F5-E5,1)-N(G5))*24,2)) | K5: =IF(OR(A5="",B5=""),"",SUMIFS(Paradas!$F$5:$F$4004,Paradas!$A$5:$A$4004,A5,Paradas!$B$5:$B$4004,B5)) | L5: =IF(J5="","",J5-N(K5)) | M5: =IF(OR(A5="",B5=""),"",COUNTIFS(Paradas!$A$5:$A$4004,A5,Paradas!$B$5:$B$4004,B5)) | N5: =IF(OR(H5="",I5=""),"",I5-H5) | O5: EXEMPLO — apagar (e as 2 paradas de exemplo)
A6: 46267 | B6: Guindaste 70 t | C6: Jhonas | D6: Querência | E6: 0.29166667 | F6: 0.70833333 | G6: 0.041666667 | H6: 1250 | I6: 1256.5 | J6: =IF(OR(E6="",F6=""),"",ROUND((MOD(F6-E6,1)-N(G6))*24,2)) | K6: =IF(OR(A6="",B6=""),"",SUMIFS(Paradas!$F$5:$F$4004,Paradas!$A$5:$A$4004,A6,Paradas!$B$5:$B$4004,B6)) | L6: =IF(J6="","",J6-N(K6)) | M6: =IF(OR(A6="",B6=""),"",COUNTIFS(Paradas!$A$5:$A$4004,A6,Paradas!$B$5:$B$4004,B6)) | N6: =IF(OR(H6="",I6=""),"",I6-H6)
J7: =IF(OR(E7="",F7=""),"",ROUND((MOD(F7-E7,1)-N(G7))*24,2)) | K7: =IF(OR(A7="",B7=""),"",SUMIFS(Paradas!$F$5:$F$4004,Paradas!$A$5:$A$4004,A7,Paradas!$B$5:$B$4004,B7)) | L7: =IF(J7="","",J7-N(K7)) | M7: =IF(OR(A7="",B7=""),"",COUNTIFS(Paradas!$A$5:$A$4004,A7,Paradas!$B$5:$B$4004,B7)) | N7: =IF(OR(H7="",I7=""),"",I7-H7)
J8: =IF(OR(E8="",F8=""),"",ROUND((MOD(F8-E8,1)-N(G8))*24,2)) | K8: =IF(OR(A8="",B8=""),"",SUMIFS(Paradas!$F$5:$F$4004,Paradas!$A$5:$A$4004,A8,Paradas!$B$5:$B$4004,B8)) | L8: =IF(J8="","",J8-N(K8)) | M8: =IF(OR(A8="",B8=""),"",COUNTIFS(Paradas!$A$5:$A$4004,A8,Paradas!$B$5:$B$4004,B8)) | N8: =IF(OR(H8="",I8=""),"",I8-H8)
J9: =IF(OR(E9="",F9=""),"",ROUND((MOD(F9-E9,1)-N(G9))*24,2)) | K9: =IF(OR(A9="",B9=""),"",SUMIFS(Paradas!$F$5:$F$4004,Paradas!$A$5:$A$4004,A9,Paradas!$B$5:$B$4004,B9)) | L9: =IF(J9="","",J9-N(K9)) | M9: =IF(OR(A9="",B9=""),"",COUNTIFS(Paradas!$A$5:$A$4004,A9,Paradas!$B$5:$B$4004,B9)) | N9: =IF(OR(H9="",I9=""),"",I9-H9)
J10: =IF(OR(E10="",F10=""),"",ROUND((MOD(F10-E10,1)-N(G10))*24,2)) | K10: =IF(OR(A10="",B10=""),"",SUMIFS(Paradas!$F$5:$F$4004,Paradas!$A$5:$A$4004,A10,Paradas!$B$5:$B$4004,B10)) | L10: =IF(J10="","",J10-N(K10)) | M10: =IF(OR(A10="",B10=""),"",COUNTIFS(Paradas!$A$5:$A$4004,A10,Paradas!$B$5:$B$4004,B10)) | N10: =IF(OR(H10="",I10=""),"",I10-H10)
J11: =IF(OR(E11="",F11=""),"",ROUND((MOD(F11-E11,1)-N(G11))*24,2)) | K11: =IF(OR(A11="",B11=""),"",SUMIFS(Paradas!$F$5:$F$4004,Paradas!$A$5:$A$4004,A11,Paradas!$B$5:$B$4004,B11)) | L11: =IF(J11="","",J11-N(K11)) | M11: =IF(OR(A11="",B11=""),"",COUNTIFS(Paradas!$A$5:$A$4004,A11,Paradas!$B$5:$B$4004,B11)) | N11: =IF(OR(H11="",I11=""),"",I11-H11)
J12: =IF(OR(E12="",F12=""),"",ROUND((MOD(F12-E12,1)-N(G12))*24,2)) | K12: =IF(OR(A12="",B12=""),"",SUMIFS(Paradas!$F$5:$F$4004,Paradas!$A$5:$A$4004,A12,Paradas!$B$5:$B$4004,B12)) | L12: =IF(J12="","",J12-N(K12)) | M12: =IF(OR(A12="",B12=""),"",COUNTIFS(Paradas!$A$5:$A$4004,A12,Paradas!$B$5:$B$4004,B12)) | N12: =IF(OR(H12="",I12=""),"",I12-H12)
J13: =IF(OR(E13="",F13=""),"",ROUND((MOD(F13-E13,1)-N(G13))*24,2)) | K13: =IF(OR(A13="",B13=""),"",SUMIFS(Paradas!$F$5:$F$4004,Paradas!$A$5:$A$4004,A13,Paradas!$B$5:$B$4004,B13)) | L13: =IF(J13="","",J13-N(K13)) | M13: =IF(OR(A13="",B13=""),"",COUNTIFS(Paradas!$A$5:$A$4004,A13,Paradas!$B$5:$B$4004,B13)) | N13: =IF(OR(H13="",I13=""),"",I13-H13)
J14: =IF(OR(E14="",F14=""),"",ROUND((MOD(F14-E14,1)-N(G14))*24,2)) | K14: =IF(OR(A14="",B14=""),"",SUMIFS(Paradas!$F$5:$F$4004,Paradas!$A$5:$A$4004,A14,Paradas!$B$5:$B$4004,B14)) | L14: =IF(J14="","",J14-N(K14)) | M14: =IF(OR(A14="",B14=""),"",COUNTIFS(Paradas!$A$5:$A$4004,A14,Paradas!$B$5:$B$4004,B14)) | N14: =IF(OR(H14="",I14=""),"",I14-H14)
J15: =IF(OR(E15="",F15=""),"",ROUND((MOD(F15-E15,1)-N(G15))*24,2)) | K15: =IF(OR(A15="",B15=""),"",SUMIFS(Paradas!$F$5:$F$4004,Paradas!$A$5:$A$4004,A15,Paradas!$B$5:$B$4004,B15)) | L15: =IF(J15="","",J15-N(K15)) | M15: =IF(OR(A15="",B15=""),"",COUNTIFS(Paradas!$A$5:$A$4004,A15,Paradas!$B$5:$B$4004,B15)) | N15: =IF(OR(H15="",I15=""),"",I15-H15)
J16: =IF(OR(E16="",F16=""),"",ROUND((MOD(F16-E16,1)-N(G16))*24,2)) | K16: =IF(OR(A16="",B16=""),"",SUMIFS(Paradas!$F$5:$F$4004,Paradas!$A$5:$A$4004,A16,Paradas!$B$5:$B$4004,B16)) | L16: =IF(J16="","",J16-N(K16)) | M16: =IF(OR(A16="",B16=""),"",COUNTIFS(Paradas!$A$5:$A$4004,A16,Paradas!$B$5:$B$4004,B16)) | N16: =IF(OR(H16="",I16=""),"",I16-H16)
J17: =IF(OR(E17="",F17=""),"",ROUND((MOD(F17-E17,1)-N(G17))*24,2)) | K17: =IF(OR(A17="",B17=""),"",SUMIFS(Paradas!$F$5:$F$4004,Paradas!$A$5:$A$4004,A17,Paradas!$B$5:$B$4004,B17)) | L17: =IF(J17="","",J17-N(K17)) | M17: =IF(OR(A17="",B17=""),"",COUNTIFS(Paradas!$A$5:$A$4004,A17,Paradas!$B$5:$B$4004,B17)) | N17: =IF(OR(H17="",I17=""),"",I17-H17)
J18: =IF(OR(E18="",F18=""),"",ROUND((MOD(F18-E18,1)-N(G18))*24,2)) | K18: =IF(OR(A18="",B18=""),"",SUMIFS(Paradas!$F$5:$F$4004,Paradas!$A$5:$A$4004,A18,Paradas!$B$5:$B$4004,B18)) | L18: =IF(J18="","",J18-N(K18)) | M18: =IF(OR(A18="",B18=""),"",COUNTIFS(Paradas!$A$5:$A$4004,A18,Paradas!$B$5:$B$4004,B18)) | N18: =IF(OR(H18="",I18=""),"",I18-H18)
... J2004: =IF(OR(E2004="",F2004=""),"",ROUND((MOD(F2004-E2004,1)-N(G2004))*24,2)) | K2004: =IF(OR(A2004="",B2004=""),"",SUMIFS(Paradas!$F$5:$F$4004,Paradas!$A$5:$A$4004,A2004,Paradas!$B$5:$B$4004,B2004)) | L2004: =IF(J2004="","",J2004-N(K2004)) | M2004: =IF(OR(A2004="",B2004=""),"",COUNTIFS(Paradas!$A$5:$A$4004,A2004,Paradas!$B$5:$B$4004,B2004)) | N2004: =IF(OR(H2004="",I2004=""),"",I2004-H2004)

Sheet Paradas
C1: REGISTRO DE PARADAS DOS EQUIPAMENTOS
C3: FS QUERÊNCIA - MT
A4: Data | B4: Equipamento | C4: Início da parada | D4: Fim da parada | E4: Motivo | F4: Duração (h) | G4: Descrição / detalhe | H4: Lançamento diário encontrado?
A5: 46266 | B5: Guindaste 30 t | C5: 0.375 | D5: 0.4375 | E5: Manutenção | F5: =IF(OR(C5="",D5=""),"",ROUND(MOD(D5-C5,1)*24,2)) | G5: Troca de mangueira hidráulica (EXEMPLO) | H5: =IF(OR(A5="",B5=""),"",IF(COUNTIFS('Lançamentos Diários'!$A$5:$A$2004,A5,'Lançamentos Diários'!$B$5:$B$2004,B5)>0,"OK","FALTA LANÇAMENTO"))
A6: 46266 | B6: Guindaste 30 t | C6: 0.58333333 | D6: 0.625 | E6: Vazamento de óleo | F6: =IF(OR(C6="",D6=""),"",ROUND(MOD(D6-C6,1)*24,2)) | G6: Vazamento no cilindro da lança (EXEMPLO) | H6: =IF(OR(A6="",B6=""),"",IF(COUNTIFS('Lançamentos Diários'!$A$5:$A$2004,A6,'Lançamentos Diários'!$B$5:$B$2004,B6)>0,"OK","FALTA LANÇAMENTO"))
F7: =IF(OR(C7="",D7=""),"",ROUND(MOD(D7-C7,1)*24,2)) | H7: =IF(OR(A7="",B7=""),"",IF(COUNTIFS('Lançamentos Diários'!$A$5:$A$2004,A7,'Lançamentos Diários'!$B$5:$B$2004,B7)>0,"OK","FALTA LANÇAMENTO"))
F8: =IF(OR(C8="",D8=""),"",ROUND(MOD(D8-C8,1)*24,2)) | H8: =IF(OR(A8="",B8=""),"",IF(COUNTIFS('Lançamentos Diários'!$A$5:$A$2004,A8,'Lançamentos Diários'!$B$5:$B$2004,B8)>0,"OK","FALTA LANÇAMENTO"))
F9: =IF(OR(C9="",D9=""),"",ROUND(MOD(D9-C9,1)*24,2)) | H9: =IF(OR(A9="",B9=""),"",IF(COUNTIFS('Lançamentos Diários'!$A$5:$A$2004,A9,'Lançamentos Diários'!$B$5:$B$2004,B9)>0,"OK","FALTA LANÇAMENTO"))
F10: =IF(OR(C10="",D10=""),"",ROUND(MOD(D10-C10,1)*24,2)) | H10: =IF(OR(A10="",B10=""),"",IF(COUNTIFS('Lançamentos Diários'!$A$5:$A$2004,A10,'Lançamentos Diários'!$B$5:$B$2004,B10)>0,"OK","FALTA LANÇAMENTO"))
F11: =IF(OR(C11="",D11=""),"",ROUND(MOD(D11-C11,1)*24,2)) | H11: =IF(OR(A11="",B11=""),"",IF(COUNTIFS('Lançamentos Diários'!$A$5:$A$2004,A11,'Lançamentos Diários'!$B$5:$B$2004,B11)>0,"OK","FALTA LANÇAMENTO"))
F12: =IF(OR(C12="",D12=""),"",ROUND(MOD(D12-C12,1)*24,2)) | H12: =IF(OR(A12="",B12=""),"",IF(COUNTIFS('Lançamentos Diários'!$A$5:$A$2004,A12,'Lançamentos Diários'!$B$5:$B$2004,B12)>0,"OK","FALTA LANÇAMENTO"))
F13: =IF(OR(C13="",D13=""),"",ROUND(MOD(D13-C13,1)*24,2)) | H13: =IF(OR(A13="",B13=""),"",IF(COUNTIFS('Lançamentos Diários'!$A$5:$A$2004,A13,'Lançamentos Diários'!$B$5:$B$2004,B13)>0,"OK","FALTA LANÇAMENTO"))
F14: =IF(OR(C14="",D14=""),"",ROUND(MOD(D14-C14,1)*24,2)) | H14: =IF(OR(A14="",B14=""),"",IF(COUNTIFS('Lançamentos Diários'!$A$5:$A$2004,A14,'Lançamentos Diários'!$B$5:$B$2004,B14)>0,"OK","FALTA LANÇAMENTO"))
F15: =IF(OR(C15="",D15=""),"",ROUND(MOD(D15-C15,1)*24,2)) | H15: =IF(OR(A15="",B15=""),"",IF(COUNTIFS('Lançamentos Diários'!$A$5:$A$2004,A15,'Lançamentos Diários'!$B$5:$B$2004,B15)>0,"OK","FALTA LANÇAMENTO"))
F16: =IF(OR(C16="",D16=""),"",ROUND(MOD(D16-C16,1)*24,2)) | H16: =IF(OR(A16="",B16=""),"",IF(COUNTIFS('Lançamentos Diários'!$A$5:$A$2004,A16,'Lançamentos Diários'!$B$5:$B$2004,B16)>0,"OK","FALTA LANÇAMENTO"))
F17: =IF(OR(C17="",D17=""),"",ROUND(MOD(D17-C17,1)*24,2)) | H17: =IF(OR(A17="",B17=""),"",IF(COUNTIFS('Lançamentos Diários'!$A$5:$A$2004,A17,'Lançamentos Diários'!$B$5:$B$2004,B17)>0,"OK","FALTA LANÇAMENTO"))
F18: =IF(OR(C18="",D18=""),"",ROUND(MOD(D18-C18,1)*24,2)) | H18: =IF(OR(A18="",B18=""),"",IF(COUNTIFS('Lançamentos Diários'!$A$5:$A$2004,A18,'Lançamentos Diários'!$B$5:$B$2004,B18)>0,"OK","FALTA LANÇAMENTO"))
... F4004: =IF(OR(C4004="",D4004=""),"",ROUND(MOD(D4004-C4004,1)*24,2)) | H4004: =IF(OR(A4004="",B4004=""),"",IF(COUNTIFS('Lançamentos Diários'!$A$5:$A$2004,A4004,'Lançamentos Diários'!$B$5:$B$2004,B4004)>0,"OK","FALTA LANÇAMENTO"))

Sheet Janeiro
B1: RESUMO MENSAL — JANEIRO
A3: Mês de referência: | B3: =DATE('Resumo Anual'!$B$3,1,1) | D3: De: | E3: =DATE(YEAR(B3),MONTH(B3),1) | F3: até: | G3: =EOMONTH(B3,0)
A5: Equipamento | B5: Dias lançados | C5: Horas totais | D5: Horas paradas | E5: Horas efetivas trabalhadas | F5: Nº de paradas | G5: Média efetiva por dia | H5: % do tempo trabalhando
A6: =IF(Equipamentos!A6="","",Equipamentos!A6) | B6: =IF(A6="","",COUNTIFS('Lançamentos Diários'!$B$5:$B$2004,$A6,'Lançamentos Diários'!$A$5:$A$2004,">="&$E$3,'Lançamentos Diários'!$A$5:$A$2004,"<="&$G$3)) | C6: =IF(A6="","",SUMIFS('Lançamentos Diários'!$J$5:$J$2004,'Lançamentos Diários'!$B$5:$B$2004,$A6,'Lançamentos Diários'!$A$5:$A$2004,">="&$E$3,'Lançamentos Diários'!$A$5:$A$2004,"<="&$G$3)) | D6: =IF(A6="","",SUMIFS(Paradas!$F$5:$F$4004,Paradas!$B$5:$B$4004,$A6,Paradas!$A$5:$A$4004,">="&$E$3,Paradas!$A$5:$A$4004,"<="&$G$3)) | E6: =IF(A6="","",C6-D6) | F6: =IF(A6="","",COUNTIFS(Paradas!$B$5:$B$4004,$A6,Paradas!$A$5:$A$4004,">="&$E$3,Paradas!$A$5:$A$4004,"<="&$G$3)) | G6: =IF(A6="","",IF(B6=0,0,E6/B6)) | H6: =IF(A6="","",IF(C6=0,0,E6/C6))
A7: =IF(Equipamentos!A7="","",Equipamentos!A7) | B7: =IF(A7="","",COUNTIFS('Lançamentos Diários'!$B$5:$B$2004,$A7,'Lançamentos Diários'!$A$5:$A$2004,">="&$E$3,'Lançamentos Diários'!$A$5:$A$2004,"<="&$G$3)) | C7: =IF(A7="","",SUMIFS('Lançamentos Diários'!$J$5:$J$2004,'Lançamentos Diários'!$B$5:$B$2004,$A7,'Lançamentos Diários'!$A$5:$A$2004,">="&$E$3,'Lançamentos Diários'!$A$5:$A$2004,"<="&$G$3)) | D7: =IF(A7="","",SUMIFS(Paradas!$F$5:$F$4004,Paradas!$B$5:$B$4004,$A7,Paradas!$A$5:$A$4004,">="&$E$3,Paradas!$A$5:$A$4004,"<="&$G$3)) | E7: =IF(A7="","",C7-D7) | F7: =IF(A7="","",COUNTIFS(Paradas!$B$5:$B$4004,$A7,Paradas!$A$5:$A$4004,">="&$E$3,Paradas!$A$5:$A$4004,"<="&$G$3)) | G7: =IF(A7="","",IF(B7=0,0,E7/B7)) | H7: =IF(A7="","",IF(C7=0,0,E7/C7))
A8: =IF(Equipamentos!A8="","",Equipamentos!A8) | B8: =IF(A8="","",COUNTIFS('Lançamentos Diários'!$B$5:$B$2004,$A8,'Lançamentos Diários'!$A$5:$A$2004,">="&$E$3,'Lançamentos Diários'!$A$5:$A$2004,"<="&$G$3)) | C8: =IF(A8="","",SUMIFS('Lançamentos Diários'!$J$5:$J$2004,'Lançamentos Diários'!$B$5:$B$2004,$A8,'Lançamentos Diários'!$A$5:$A$2004,">="&$E$3,'Lançamentos Diários'!$A$5:$A$2004,"<="&$G$3)) | D8: =IF(A8="","",SUMIFS(Paradas!$F$5:$F$4004,Paradas!$B$5:$B$4004,$A8,Paradas!$A$5:$A$4004,">="&$E$3,Paradas!$A$5:$A$4004,"<="&$G$3)) | E8: =IF(A8="","",C8-D8) | F8: =IF(A8="","",COUNTIFS(Paradas!$B$5:$B$4004,$A8,Paradas!$A$5:$A$4004,">="&$E$3,Paradas!$A$5:$A$4004,"<="&$G$3)) | G8: =IF(A8="","",IF(B8=0,0,E8/B8)) | H8: =IF(A8="","",IF(C8=0,0,E8/C8))
A9: =IF(Equipamentos!A9="","",Equipamentos!A9) | B9: =IF(A9="","",COUNTIFS('Lançamentos Diários'!$B$5:$B$2004,$A9,'Lançamentos Diários'!$A$5:$A$2004,">="&$E$3,'Lançamentos Diários'!$A$5:$A$2004,"<="&$G$3)) | C9: =IF(A9="","",SUMIFS('Lançamentos Diários'!$J$5:$J$2004,'Lançamentos Diários'!$B$5:$B$2004,$A9,'Lançamentos Diários'!$A$5:$A$2004,">="&$E$3,'Lançamentos Diários'!$A$5:$A$2004,"<="&$G$3)) | D9: =IF(A9="","",SUMIFS(Paradas!$F$5:$F$4004,Paradas!$B$5:$B$4004,$A9,Paradas!$A$5:$A$4004,">="&$E$3,Paradas!$A$5:$A$4004,"<="&$G$3)) | E9: =IF(A9="","",C9-D9) | F9: =IF(A9="","",COUNTIFS(Paradas!$B$5:$B$4004,$A9,Paradas!$A$5:$A$4004,">="&$E$3,Paradas!$A$5:$A$4004,"<="&$G$3)) | G9: =IF(A9="","",IF(B9=0,0,E9/B9)) | H9: =IF(A9="","",IF(C9=0,0,E9/C9))
A10: =IF(Equipamentos!A10="","",Equipamentos!A10) | B10: =IF(A10="","",COUNTIFS('Lançamentos Diários'!$B$5:$B$2004,$A10,'Lançamentos Diários'!$A$5:$A$2004,">="&$E$3,'Lançamentos Diários'!$A$5:$A$2004,"<="&$G$3)) | C10: =IF(A10="","",SUMIFS('Lançamentos Diários'!$J$5:$J$2004,'Lançamentos Diários'!$B$5:$B$2004,$A10,'Lançamentos Diários'!$A$5:$A$2004,">="&$E$3,'Lançamentos Diários'!$A$5:$A$2004,"<="&$G$3)) | D10: =IF(A10="","",SUMIFS(Paradas!$F$5:$F$4004,Paradas!$B$5:$B$4004,$A10,Paradas!$A$5:$A$4004,">="&$E$3,Paradas!$A$5:$A$4004,"<="&$G$3)) | E10: =IF(A10="","",C10-D10) | F10: =IF(A10="","",COUNTIFS(Paradas!$B$5:$B$4004,$A10,Paradas!$A$5:$A$4004,">="&$E$3,Paradas!$A$5:$A$4004,"<="&$G$3)) | G10: =IF(A10="","",IF(B10=0,0,E10/B10)) | H10: =IF(A10="","",IF(C10=0,0,E10/C10))
A11: =IF(Equipamentos!A11="","",Equipamentos!A11) | B11: =IF(A11="","",COUNTIFS('Lançamentos Diários'!$B$5:$B$2004,$A11,'Lançamentos Diários'!$A$5:$A$2004,">="&$E$3,'Lançamentos Diários'!$A$5:$A$2004,"<="&$G$3)) | C11: =IF(A11="","",SUMIFS('Lançamentos Diários'!$J$5:$J$2004,'Lançamentos Diários'!$B$5:$B$2004,$A11,'Lançamentos Diários'!$A$5:$A$2004,">="&$E$3,'Lançamentos Diários'!$A$5:$A$2004,"<="&$G$3)) | D11: =IF(A11="","",SUMIFS(Paradas!$F$5:$F$4004,Paradas!$B$5:$B$4004,$A11,Paradas!$A$5:$A$4004,">="&$E$3,Paradas!$A$5:$A$4004,"<="&$G$3)) | E11: =IF(A11="","",C11-D11) | F11: =IF(A11="","",COUNTIFS(Paradas!$B$5:$B$4004,$A11,Paradas!$A$5:$A$4004,">="&$E$3,Paradas!$A$5:$A$4004,"<="&$G$3)) | G11: =IF(A11="","",IF(B11=0,0,E11/B11)) | H11: =IF(A11="","",IF(C11=0,0,E11/C11))
A12: TOTAL | B12: =SUM(B6:B11) | C12: =SUM(C6:C11) | D12: =SUM(D6:D11) | E12: =SUM(E6:E11) | F12: =SUM(F6:F11) | H12: =IF(C12=0,0,E12/C12)
A15: HORAS PARADAS POR MOTIVO NO MÊS
A16: Motivo | B16: =IF(Equipamentos!A6="","",Equipamentos!A6) | C16: =IF(Equipamentos!A7="","",Equipamentos!A7) | D16: =IF(Equipamentos!A8="","",Equipamentos!A8) | E16: =IF(Equipamentos!A9="","",Equipamentos!A9) | F16: =IF(Equipamentos!A10="","",Equipamentos!A10) | G16: =IF(Equipamentos!A11="","",Equipamentos!A11) | H16: Total
A17: =IF('Motivos de Parada'!A7="","",'Motivos de Parada'!A7) | B17: =IF(OR($A17="",B$16=""),"",SUMIFS(Paradas!$F$5:$F$4004,Paradas!$E$5:$E$4004,$A17,Paradas!$B$5:$B$4004,B$16,Paradas!$A$5:$A$4004,">="&$E$3,Paradas!$A$5:$A$4004,"<="&$G$3)) | C17: =IF(OR($A17="",C$16=""),"",SUMIFS(Paradas!$F$5:$F$4004,Paradas!$E$5:$E$4004,$A17,Paradas!$B$5:$B$4004,C$16,Paradas!$A$5:$A$4004,">="&$E$3,Paradas!$A$5:$A$4004,"<="&$G$3)) | D17: =IF(OR($A17="",D$16=""),"",SUMIFS(Paradas!$F$5:$F$4004,Paradas!$E$5:$E$4004,$A17,Paradas!$B$5:$B$4004,D$16,Paradas!$A$5:$A$4004,">="&$E$3,Paradas!$A$5:$A$4004,"<="&$G$3)) | E17: =IF(OR($A17="",E$16=""),"",SUMIFS(Paradas!$F$5:$F$4004,Paradas!$E$5:$E$4004,$A17,Paradas!$B$5:$B$4004,E$16,Paradas!$A$5:$A$4004,">="&$E$3,Paradas!$A$5:$A$4004,"<="&$G$3)) | F17: =IF(OR($A17="",F$16=""),"",SUMIFS(Paradas!$F$5:$F$4004,Paradas!$E$5:$E$4004,$A17,Paradas!$B$5:$B$4004,F$16,Paradas!$A$5:$A$4004,">="&$E$3,Paradas!$A$5:$A$4004,"<="&$G$3)) | G17: =IF(OR($A17="",G$16=""),"",SUMIFS(Paradas!$F$5:$F$4004,Paradas!$E$5:$E$4004,$A17,Paradas!$B$5:$B$4004,G$16,Paradas!$A$5:$A$4004,">="&$E$3,Paradas!$A$5:$A$4004,"<="&$G$3)) | H17: =IF($A17="","",SUM(B17:G17))
A18: =IF('Motivos de Parada'!A8="","",'Motivos de Parada'!A8) | B18: =IF(OR($A18="",B$16=""),"",SUMIFS(Paradas!$F$5:$F$4004,Paradas!$E$5:$E$4004,$A18,Paradas!$B$5:$B$4004,B$16,Paradas!$A$5:$A$4004,">="&$E$3,Paradas!$A$5:$A$4004,"<="&$G$3)) | C18: =IF(OR($A18="",C$16=""),"",SUMIFS(Paradas!$F$5:$F$4004,Paradas!$E$5:$E$4004,$A18,Paradas!$B$5:$B$4004,C$16,Paradas!$A$5:$A$4004,">="&$E$3,Paradas!$A$5:$A$4004,"<="&$G$3)) | D18: =IF(OR($A18="",D$16=""),"",SUMIFS(Paradas!$F$5:$F$4004,Paradas!$E$5:$E$4004,$A18,Paradas!$B$5:$B$4004,D$16,Paradas!$A$5:$A$4004,">="&$E$3,Paradas!$A$5:$A$4004,"<="&$G$3)) | E18: =IF(OR($A18="",E$16=""),"",SUMIFS(Paradas!$F$5:$F$4004,Paradas!$E$5:$E$4004,$A18,Paradas!$B$5:$B$4004,E$16,Paradas!$A$5:$A$4004,">="&$E$3,Paradas!$A$5:$A$4004,"<="&$G$3)) | F18: =IF(OR($A18="",F$16=""),"",SUMIFS(Paradas!$F$5:$F$4004,Paradas!$E$5:$E$4004,$A18,Paradas!$B$5:$B$4004,F$16,Paradas!$A$5:$A$4004,">="&$E$3,Paradas!$A$5:$A$4004,"<="&$G$3)) | G18: =IF(OR($A18="",G$16=""),"",SUMIFS(Paradas!$F$5:$F$4004,Paradas!$E$5:$E$4004,$A18,Paradas!$B$5:$B$4004,G$16,Paradas!$A$5:$A$4004,">="&$E$3,Paradas!$A$5:$A$4004,"<="&$G$3)) | H18: =IF($A18="","",SUM(B18:G18))
A19: =IF('Motivos de Parada'!A9="","",'Motivos de Parada'!A9) | B19: =IF(OR($A19="",B$16=""),"",SUMIFS(Paradas!$F$5:$F$4004,Paradas!$E$5:$E$4004,$A19,Paradas!$B$5:$B$4004,B$16,Paradas!$A$5:$A$4004,">="&$E$3,Paradas!$A$5:$A$4004,"<="&$G$3)) | C19: =IF(OR($A19="",C$16=""),"",SUMIFS(Paradas!$F$5:$F$4004,Paradas!$E$5:$E$4004,$A19,Paradas!$B$5:$B$4004,C$16,Paradas!$A$5:$A$4004,">="&$E$3,Paradas!$A$5:$A$4004,"<="&$G$3)) | D19: =IF(OR($A19="",D$16=""),"",SUMIFS(Paradas!$F$5:$F$4004,Paradas!$E$5:$E$4004,$A19,Paradas!$B$5:$B$4004,D$16,Paradas!$A$5:$A$4004,">="&$E$3,Paradas!$A$5:$A$4004,"<="&$G$3)) | E19: =IF(OR($A19="",E$16=""),"",SUMIFS(Paradas!$F$5:$F$4004,Paradas!$E$5:$E$4004,$A19,Paradas!$B$5:$B$4004,E$16,Paradas!$A$5:$A$4004,">="&$E$3,Paradas!$A$5:$A$4004,"<="&$G$3)) | F19: =IF(OR($A19="",F$16=""),"",SUMIFS(Paradas!$F$5:$F$4004,Paradas!$E$5:$E$4004,$A19,Paradas!$B$5:$B$4004,F$16,Paradas!$A$5:$A$4004,">="&$E$3,Paradas!$A$5:$A$4004,"<="&$G$3)) | G19: =IF(OR($A19="",G$16=""),"",SUMIFS(Paradas!$F$5:$F$4004,Paradas!$E$5:$E$4004,$A19,Paradas!$B$5:$B$4004,G$16,Paradas!$A$5:$A$4004,">="&$E$3,Paradas!$A$5:$A$4004,"<="&$G$3)) | H19: =IF($A19="","",SUM(B19:G19))
A20: =IF('Motivos de Parada'!A10="","",'Motivos de Parada'!A10) | B20: =IF(OR($A20="",B$16=""),"",SUMIFS(Paradas!$F$5:$F$4004,Paradas!$E$5:$E$4004,$A20,Paradas!$B$5:$B$4004,B$16,Paradas!$A$5:$A$4004,">="&$E$3,Paradas!$A$5:$A$4004,"<="&$G$3)) | C20: =IF(OR($A20="",C$16=""),"",SUMIFS(Paradas!$F$5:$F$4004,Paradas!$E$5:$E$4004,$A20,Paradas!$B$5:$B$4004,C$16,Paradas!$A$5:$A$4004,">="&$E$3,Paradas!$A$5:$A$4004,"<="&$G$3)) | D20: =IF(OR($A20="",D$16=""),"",SUMIFS(Paradas!$F$5:$F$4004,Paradas!$E$5:$E$4004,$A20,Paradas!$B$5:$B$4004,D$16,Paradas!$A$5:$A$4004,">="&$E$3,Paradas!$A$5:$A$4004,"<="&$G$3)) | E20: =IF(OR($A20="",E$16=""),"",SUMIFS(Paradas!$F$5:$F$4004,Paradas!$E$5:$E$4004,$A20,Paradas!$B$5:$B$4004,E$16,Paradas!$A$5:$A$4004,">="&$E$3,Paradas!$A$5:$A$4004,"<="&$G$3)) | F20: =IF(OR($A20="",F$16=""),"",SUMIFS(Paradas!$F$5:$F$4004,Paradas!$E$5:$E$4004,$A20,Paradas!$B$5:$B$4004,F$16,Paradas!$A$5:$A$4004,">="&$E$3,Paradas!$A$5:$A$4004,"<="&$G$3)) | G20: =IF(OR($A20="",G$16=""),"",SUMIFS(Paradas!$F$5:$F$4004,Paradas!$E$5:$E$4004,$A20,Paradas!$B$5:$B$4004,G$16,Paradas!$A$5:$A$4004,">="&$E$3,Paradas!$A$5:$A$4004,"<="&$G$3)) | H20: =IF($A20="","",SUM(B20:G20))
A21: =IF('Motivos de Parada'!A11="","",'Motivos de Parada'!A11) | B21: =IF(OR($A21="",B$16=""),"",SUMIFS(Paradas!$F$5:$F$4004,Paradas!$E$5:$E$4004,$A21,Paradas!$B$5:$B$4004,B$16,Paradas!$A$5:$A$4004,">="&$E$3,Paradas!$A$5:$A$4004,"<="&$G$3)) | C21: =IF(OR($A21="",C$16=""),"",SUMIFS(Paradas!$F$5:$F$4004,Paradas!$E$5:$E$4004,$A21,Paradas!$B$5:$B$4004,C$16,Paradas!$A$5:$A$4004,">="&$E$3,Paradas!$A$5:$A$4004,"<="&$G$3)) | D21: =IF(OR($A21="",D$16=""),"",SUMIFS(Paradas!$F$5:$F$4004,Paradas!$E$5:$E$4004,$A21,Paradas!$B$5:$B$4004,D$16,Paradas!$A$5:$A$4004,">="&$E$3,Paradas!$A$5:$A$4004,"<="&$G$3)) | E21: =IF(OR($A21="",E$16=""),"",SUMIFS(Paradas!$F$5:$F$4004,Paradas!$E$5:$E$4004,$A21,Paradas!$B$5:$B$4004,E$16,Paradas!$A$5:$A$4004,">="&$E$3,Paradas!$A$5:$A$4004,"<="&$G$3)) | F21: =IF(OR($A21="",F$16=""),"",SUMIFS(Paradas!$F$5:$F$4004,Paradas!$E$5:$E$4004,$A21,Paradas!$B$5:$B$4004,F$16,Paradas!$A$5:$A$4004,">="&$E$3,Paradas!$A$5:$A$4004,"<="&$G$3)) | G21: =IF(OR($A21="",G$16=""),"",SUMIFS(Paradas!$F$5:$F$4004,Paradas!$E$5:$E$4004,$A21,Paradas!$B$5:$B$4004,G$16,Paradas!$A$5:$A$4004,">="&$E$3,Paradas!$A$5:$A$4004,"<="&$G$3)) | H21: =IF($A21="","",SUM(B21:G21))
A22: =IF('Motivos de Parada'!A12="","",'Motivos de Parada'!A12) | B22: =IF(OR($A22="",B$16=""),"",SUMIFS(Paradas!$F$5:$F$4004,Paradas!$E$5:$E$4004,$A22,Paradas!$B$5:$B$4004,B$16,Paradas!$A$5:$A$4004,">="&$E$3,Paradas!$A$5:$A$4004,"<="&$G$3)) | C22: =IF(OR($A22="",C$16=""),"",SUMIFS(Paradas!$F$5:$F$4004,Paradas!$E$5:$E$4004,$A22,Paradas!$B$5:$B$4004,C$16,Paradas!$A$5:$A$4004,">="&$E$3,Paradas!$A$5:$A$4004,"<="&$G$3)) | D22: =IF(OR($A22="",D$16=""),"",SUMIFS(Paradas!$F$5:$F$4004,Paradas!$E$5:$E$4004,$A22,Paradas!$B$5:$B$4004,D$16,Paradas!$A$5:$A$4004,">="&$E$3,Paradas!$A$5:$A$4004,"<="&$G$3)) | E22: =IF(OR($A22="",E$16=""),"",SUMIFS(Paradas!$F$5:$F$4004,Paradas!$E$5:$E$4004,$A22,Paradas!$B$5:$B$4004,E$16,Paradas!$A$5:$A$4004,">="&$E$3,Paradas!$A$5:$A$4004,"<="&$G$3)) | F22: =IF(OR($A22="",F$16=""),"",SUMIFS(Paradas!$F$5:$F$4004,Paradas!$E$5:$E$4004,$A22,Paradas!$B$5:$B$4004,F$16,Paradas!$A$5:$A$4004,">="&$E$3,Paradas!$A$5:$A$4004,"<="&$G$3)) | G22: =IF(OR($A22="",G$16=""),"",SUMIFS(Paradas!$F$5:$F$4004,Paradas!$E$5:$E$4004,$A22,Paradas!$B$5:$B$4004,G$16,Paradas!$A$5:$A$4004,">="&$E$3,Paradas!$A$5:$A$4004,"<="&$G$3)) | H22: =IF($A22="","",SUM(B22:G22))
A23: =IF('Motivos de Parada'!A13="","",'Motivos de Parada'!A13) | B23: =IF(OR($A23="",B$16=""),"",SUMIFS(Paradas!$F$5:$F$4004,Paradas!$E$5:$E$4004,$A23,Paradas!$B$5:$B$4004,B$16,Paradas!$A$5:$A$4004,">="&$E$3,Paradas!$A$5:$A$4004,"<="&$G$3)) | C23: =IF(OR($A23="",C$16=""),"",SUMIFS(Paradas!$F$5:$F$4004,Paradas!$E$5:$E$4004,$A23,Paradas!$B$5:$B$4004,C$16,Paradas!$A$5:$A$4004,">="&$E$3,Paradas!$A$5:$A$4004,"<="&$G$3)) | D23: =IF(OR($A23="",D$16=""),"",SUMIFS(Paradas!$F$5:$F$4004,Paradas!$E$5:$E$4004,$A23,Paradas!$B$5:$B$4004,D$16,Paradas!$A$5:$A$4004,">="&$E$3,Paradas!$A$5:$A$4004,"<="&$G$3)) | E23: =IF(OR($A23="",E$16=""),"",SUMIFS(Paradas!$F$5:$F$4004,Paradas!$E$5:$E$4004,$A23,Paradas!$B$5:$B$4004,E$16,Paradas!$A$5:$A$4004,">="&$E$3,Paradas!$A$5:$A$4004,"<="&$G$3)) | F23: =IF(OR($A23="",F$16=""),"",SUMIFS(Paradas!$F$5:$F$4004,Paradas!$E$5:$E$4004,$A23,Paradas!$B$5:$B$4004,F$16,Paradas!$A$5:$A$4004,">="&$E$3,Paradas!$A$5:$A$4004,"<="&$G$3)) | G23: =IF(OR($A23="",G$16=""),"",SUMIFS(Paradas!$F$5:$F$4004,Paradas!$E$5:$E$4004,$A23,Paradas!$B$5:$B$4004,G$16,Paradas!$A$5:$A$4004,">="&$E$3,Paradas!$A$5:$A$4004,"<="&$G$3)) | H23: =IF($A23="","",SUM(B23:G23))
A24: =IF('Motivos de Parada'!A14="","",'Motivos de Parada'!A14) | B24: =IF(OR($A24="",B$16=""),"",SUMIFS(Paradas!$F$5:$F$4004,Paradas!$E$5:$E$4004,$A24,Paradas!$B$5:$B$4004,B$16,Paradas!$A$5:$A$4004,">="&$E$3,Paradas!$A$5:$A$4004,"<="&$G$3)) | C24: =IF(OR($A24="",C$16=""),"",SUMIFS(Paradas!$F$5:$F$4004,Paradas!$E$5:$E$4004,$A24,Paradas!$B$5:$B$4004,C$16,Paradas!$A$5:$A$4004,">="&$E$3,Paradas!$A$5:$A$4004,"<="&$G$3)) | D24: =IF(OR($A24="",D$16=""),"",SUMIFS(Paradas!$F$5:$F$4004,Paradas!$E$5:$E$4004,$A24,Paradas!$B$5:$B$4004,D$16,Paradas!$A$5:$A$4004,">="&$E$3,Paradas!$A$5:$A$4004,"<="&$G$3)) | E24: =IF(OR($A24="",E$16=""),"",SUMIFS(Paradas!$F$5:$F$4004,Paradas!$E$5:$E$4004,$A24,Paradas!$B$5:$B$4004,E$16,Paradas!$A$5:$A$4004,">="&$E$3,Paradas!$A$5:$A$4004,"<="&$G$3)) | F24: =IF(OR($A24="",F$16=""),"",SUMIFS(Paradas!$F$5:$F$4004,Paradas!$E$5:$E$4004,$A24,Paradas!$B$5:$B$4004,F$16,Paradas!$A$5:$A$4004,">="&$E$3,Paradas!$A$5:$A$4004,"<="&$G$3)) | G24: =IF(OR($A24="",G$16=""),"",SUMIFS(Paradas!$F$5:$F$4004,Paradas!$E$5:$E$4004,$A24,Paradas!$B$5:$B$4004,G$16,Paradas!$A$5:$A$4004,">="&$E$3,Paradas!$A$5:$A$4004,"<="&$G$3)) | H24: =IF($A24="","",SUM(B24:G24))
A25: =IF('Motivos de Parada'!A15="","",'Motivos de Parada'!A15) | B25: =IF(OR($A25="",B$16=""),"",SUMIFS(Paradas!$F$5:$F$4004,Paradas!$E$5:$E$4004,$A25,Paradas!$B$5:$B$4004,B$16,Paradas!$A$5:$A$4004,">="&$E$3,Paradas!$A$5:$A$4004,"<="&$G$3)) | C25: =IF(OR($A25="",C$16=""),"",SUMIFS(Paradas!$F$5:$F$4004,Paradas!$E$5:$E$4004,$A25,Paradas!$B$5:$B$4004,C$16,Paradas!$A$5:$A$4004,">="&$E$3,Paradas!$A$5:$A$4004,"<="&$G$3)) | D25: =IF(OR($A25="",D$16=""),"",SUMIFS(Paradas!$F$5:$F$4004,Paradas!$E$5:$E$4004,$A25,Paradas!$B$5:$B$4004,D$16,Paradas!$A$5:$A$4004,">="&$E$3,Paradas!$A$5:$A$4004,"<="&$G$3)) | E25: =IF(OR($A25="",E$16=""),"",SUMIFS(Paradas!$F$5:$F$4004,Paradas!$E$5:$E$4004,$A25,Paradas!$B$5:$B$4004,E$16,Paradas!$A$5:$A$4004,">="&$E$3,Paradas!$A$5:$A$4004,"<="&$G$3)) | F25: =IF(OR($A25="",F$16=""),"",SUMIFS(Paradas!$F$5:$F$4004,Paradas!$E$5:$E$4004,$A25,Paradas!$B$5:$B$4004,F$16,Paradas!$A$5:$A$4004,">="&$E$3,Paradas!$A$5:$A$4004,"<="&$G$3)) | G25: =IF(OR($A25="",G$16=""),"",SUMIFS(Paradas!$F$5:$F$4004,Paradas!$E$5:$E$4004,$A25,Paradas!$B$5:$B$4004,G$16,Paradas!$A$5:$A$4004,">="&$E$3,Paradas!$A$5:$A$4004,"<="&$G$3)) | H25: =IF($A25="","",SUM(B25:G25))
A26: =IF('Motivos de Parada'!A16="","",'Motivos de Parada'!A16) | B26: =IF(OR($A26="",B$16=""),"",SUMIFS(Paradas!$F$5:$F$4004,Paradas!$E$5:$E$4004,$A26,Paradas!$B$5:$B$4004,B$16,Paradas!$A$5:$A$4004,">="&$E$3,Paradas!$A$5:$A$4004,"<="&$G$3)) | C26: =IF(OR($A26="",C$16=""),"",SUMIFS(Paradas!$F$5:$F$4004,Paradas!$E$5:$E$4004,$A26,Paradas!$B$5:$B$4004,C$16,Paradas!$A$5:$A$4004,">="&$E$3,Paradas!$A$5:$A$4004,"<="&$G$3)) | D26: =IF(OR($A26="",D$16=""),"",SUMIFS(Paradas!$F$5:$F$4004,Paradas!$E$5:$E$4004,$A26,Paradas!$B$5:$B$4004,D$16,Paradas!$A$5:$A$4004,">="&$E$3,Paradas!$A$5:$A$4004,"<="&$G$3)) | E26: =IF(OR($A26="",E$16=""),"",SUMIFS(Paradas!$F$5:$F$4004,Paradas!$E$5:$E$4004,$A26,Paradas!$B$5:$B$4004,E$16,Paradas!$A$5:$A$4004,">="&$E$3,Paradas!$A$5:$A$4004,"<="&$G$3)) | F26: =IF(OR($A26="",F$16=""),"",SUMIFS(Paradas!$F$5:$F$4004,Paradas!$E$5:$E$4004,$A26,Paradas!$B$5:$B$4004,F$16,Paradas!$A$5:$A$4004,">="&$E$3,Paradas!$A$5:$A$4004,"<="&$G$3)) | G26: =IF(OR($A26="",G$16=""),"",SUMIFS(Paradas!$F$5:$F$4004,Paradas!$E$5:$E$4004,$A26,Paradas!$B$5:$B$4004,G$16,Paradas!$A$5:$A$4004,">="&$E$3,Paradas!$A$5:$A$4004,"<="&$G$3)) | H26: =IF($A26="","",SUM(B26:G26))
A27: =IF('Motivos de Parada'!A17="","",'Motivos de Parada'!A17) | B27: =IF(OR($A27="",B$16=""),"",SUMIFS(Paradas!$F$5:$F$4004,Paradas!$E$5:$E$4004,$A27,Paradas!$B$5:$B$4004,B$16,Paradas!$A$5:$A$4004,">="&$E$3,Paradas!$A$5:$A$4004,"<="&$G$3)) | C27: =IF(OR($A27="",C$16=""),"",SUMIFS(Paradas!$F$5:$F$4004,Paradas!$E$5:$E$4004,$A27,Paradas!$B$5:$B$4004,C$16,Paradas!$A$5:$A$4004,">="&$E$3,Paradas!$A$5:$A$4004,"<="&$G$3)) | D27: =IF(OR($A27="",D$16=""),"",SUMIFS(Paradas!$F$5:$F$4004,Paradas!$E$5:$E$4004,$A27,Paradas!$B$5:$B$4004,D$16,Paradas!$A$5:$A$4004,">="&$E$3,Paradas!$A$5:$A$4004,"<="&$G$3)) | E27: =IF(OR($A27="",E$16=""),"",SUMIFS(Paradas!$F$5:$F$4004,Paradas!$E$5:$E$4004,$A27,Paradas!$B$5:$B$4004,E$16,Paradas!$A$5:$A$4004,">="&$E$3,Paradas!$A$5:$A$4004,"<="&$G$3)) | F27: =IF(OR($A27="",F$16=""),"",SUMIFS(Paradas!$F$5:$F$4004,Paradas!$E$5:$E$4004,$A27,Paradas!$B$5:$B$4004,F$16,Paradas!$A$5:$A$4004,">="&$E$3,Paradas!$A$5:$A$4004,"<="&$G$3)) | G27: =IF(OR($A27="",G$16=""),"",SUMIFS(Paradas!$F$5:$F$4004,Paradas!$E$5:$E$4004,$A27,Paradas!$B$5:$B$4004,G$16,Paradas!$A$5:$A$4004,">="&$E$3,Paradas!$A$5:$A$4004,"<="&$G$3)) | H27: =IF($A27="","",SUM(B27:G27))
A28: =IF('Motivos de Parada'!A18="","",'Motivos de Parada'!A18) | B28: =IF(OR($A28="",B$16=""),"",SUMIFS(Paradas!$F$5:$F$4004,Paradas!$E$5:$E$4004,$A28,Paradas!$B$5:$B$4004,B$16,Paradas!$A$5:$A$4004,">="&$E$3,Paradas!$A$5:$A$4004,"<="&$G$3)) | C28: =IF(OR($A28="",C$16=""),"",SUMIFS(Paradas!$F$5:$F$4004,Paradas!$E$5:$E$4004,$A28,Paradas!$B$5:$B$4004,C$16,Paradas!$A$5:$A$4004,">="&$E$3,Paradas!$A$5:$A$4004,"<="&$G$3)) | D28: =IF(OR($A28="",D$16=""),"",SUMIFS(Paradas!$F$5:$F$4004,Paradas!$E$5:$E$4004,$A28,Paradas!$B$5:$B$4004,D$16,Paradas!$A$5:$A$4004,">="&$E$3,Paradas!$A$5:$A$4004,"<="&$G$3)) | E28: =IF(OR($A28="",E$16=""),"",SUMIFS(Paradas!$F$5:$F$4004,Paradas!$E$5:$E$4004,$A28,Paradas!$B$5:$B$4004,E$16,Paradas!$A$5:$A$4004,">="&$E$3,Paradas!$A$5:$A$4004,"<="&$G$3)) | F28: =IF(OR($A28="",F$16=""),"",SUMIFS(Paradas!$F$5:$F$4004,Paradas!$E$5:$E$4004,$A28,Paradas!$B$5:$B$4004,F$16,Paradas!$A$5:$A$4004,">="&$E$3,Paradas!$A$5:$A$4004,"<="&$G$3)) | G28: =IF(OR($A28="",G$16=""),"",SUMIFS(Paradas!$F$5:$F$4004,Paradas!$E$5:$E$4004,$A28,Paradas!$B$5:$B$4004,G$16,Paradas!$A$5:$A$4004,">="&$E$3,Paradas!$A$5:$A$4004,"<="&$G$3)) | H28: =IF($A28="","",SUM(B28:G28))
... A36: =IF('Motivos de Parada'!A26="","",'Motivos de Parada'!A26) | B36: =IF(OR($A36="",B$16=""),"",SUMIFS(Paradas!$F$5:$F$4004,Paradas!$E$5:$E$4004,$A36,Paradas!$B$5:$B$4004,B$16,Paradas!$A$5:$A$4004,">="&$E$3,Paradas!$A$5:$A$4004,"<="&$G$3)) | C36: =IF(OR($A36="",C$16=""),"",SUMIFS(Paradas!$F$5:$F$4004,Paradas!$E$5:$E$4004,$A36,Paradas!$B$5:$B$4004,C$16,Paradas!$A$5:$A$4004,">="&$E$3,Paradas!$A$5:$A$4004,"<="&$G$3)) | D36: =IF(OR($A36="",D$16=""),"",SUMIFS(Paradas!$F$5:$F$4004,Paradas!$E$5:$E$4004,$A36,Paradas!$B$5:$B$4004,D$16,Paradas!$A$5:$A$4004,">="&$E$3,Paradas!$A$5:$A$4004,"<="&$G$3)) | E36: =IF(OR($A36="",E$16=""),"",SUMIFS(Paradas!$F$5:$F$4004,Paradas!$E$5:$E$4004,$A36,Paradas!$B$5:$B$4004,E$16,Paradas!$A$5:$A$4004,">="&$E$3,Paradas!$A$5:$A$4004,"<="&$G$3)) | F36: =IF(OR($A36="",F$16=""),"",SUMIFS(Paradas!$F$5:$F$4004,Paradas!$E$5:$E$4004,$A36,Paradas!$B$5:$B$4004,F$16,Paradas!$A$5:$A$4004,">="&$E$3,Paradas!$A$5:$A$4004,"<="&$G$3)) | G36: =IF(OR($A36="",G$16=""),"",SUMIFS(Paradas!$F$5:$F$4004,Paradas!$E$5:$E$4004,$A36,Paradas!$B$5:$B$4004,G$16,Paradas!$A$5:$A$4004,">="&$E$3,Paradas!$A$5:$A$4004,"<="&$G$3)) | H36: =IF($A36="","",SUM(B36:G36))
A37: TOTAL | B37: =SUM(B17:B36) | C37: =SUM(C17:C36) | D37: =SUM(D17:D36) | E37: =SUM(E17:E36) | F37: =SUM(F17:F36) | G37: =SUM(G17:G36) | H37: =SUM(H17:H36)

Sheet Fevereiro
B1: RESUMO MENSAL — FEVEREIRO
A3: Mês de referência: | B3: =DATE('Resumo Anual'!$B$3,2,1) | D3: De: | E3: =DATE(YEAR(B3),MONTH(B3),1) | F3: até: | G3: =EOMONTH(B3,0)
A5: Equipamento | B5: Dias lançados | C5: Horas totais | D5: Horas paradas | E5: Horas efetivas trabalhadas | F5: Nº de paradas | G5: Média efetiva por dia | H5: % do tempo trabalhando
A6: =IF(Equipamentos!A6="","",Equipamentos!A6) | B6: =IF(A6="","",COUNTIFS('Lançamentos Diários'!$B$5:$B$2004,$A6,'Lançamentos Diários'!$A$5:$A$2004,">="&$E$3,'Lançamentos Diários'!$A$5:$A$2004,"<="&$G$3)) | C6: =IF(A6="","",SUMIFS('Lançamentos Diários'!$J$5:$J$2004,'Lançamentos Diários'!$B$5:$B$2004,$A6,'Lançamentos Diários'!$A$5:$A$2004,">="&$E$3,'Lançamentos Diários'!$A$5:$A$2004,"<="&$G$3)) | D6: =IF(A6="","",SUMIFS(Paradas!$F$5:$F$4004,Paradas!$B$5:$B$4004,$A6,Paradas!$A$5:$A$4004,">="&$E$3,Paradas!$A$5:$A$4004,"<="&$G$3)) | E6: =IF(A6="","",C6-D6) | F6: =IF(A6="","",COUNTIFS(Paradas!$B$5:$B$4004,$A6,Paradas!$A$5:$A$4004,">="&$E$3,Paradas!$A$5:$A$4004,"<="&$G$3)) | G6: =IF(A6="","",IF(B6=0,0,E6/B6)) | H6: =IF(A6="","",IF(C6=0,0,E6/C6))
A7: =IF(Equipamentos!A7="","",Equipamentos!A7) | B7: =IF(A7="","",COUNTIFS('Lançamentos Diários'!$B$5:$B$2004,$A7,'Lançamentos Diários'!$A$5:$A$2004,">="&$E$3,'Lançamentos Diários'!$A$5:$A$2004,"<="&$G$3)) | C7: =IF(A7="","",SUMIFS('Lançamentos Diários'!$J$5:$J$2004,'Lançamentos Diários'!$B$5:$B$2004,$A7,'Lançamentos Diários'!$A$5:$A$2004,">="&$E$3,'Lançamentos Diários'!$A$5:$A$2004,"<="&$G$3)) | D7: =IF(A7="","",SUMIFS(Paradas!$F$5:$F$4004,Paradas!$B$5:$B$4004,$A7,Paradas!$A$5:$A$4004,">="&$E$3,Paradas!$A$5:$A$4004,"<="&$G$3)) | E7: =IF(A7="","",C7-D7) | F7: =IF(A7="","",COUNTIFS(Paradas!$B$5:$B$4004,$A7,Paradas!$A$5:$A$4004,">="&$E$3,Paradas!$A$5:$A$4004,"<="&$G$3)) | G7: =IF(A7="","",IF(B7=0,0,E7/B7)) | H7: =IF(A7="","",IF(C7=0,0,E7/C7))
A8: =IF(Equipamentos!A8="","",Equipamentos!A8) | B8: =IF(A8="","",COUNTIFS('Lançamentos Diários'!$B$5:$B$2004,$A8,'Lançamentos Diários'!$A$5:$A$2004,">="&$E$3,'Lançamentos Diários'!$A$5:$A$2004,"<="&$G$3)) | C8: =IF(A8="","",SUMIFS('Lançamentos Diários'!$J$5:$J$2004,'Lançamentos Diários'!$B$5:$B$2004,$A8,'Lançamentos Diários'!$A$5:$A$2004,">="&$E$3,'Lançamentos Diários'!$A$5:$A$2004,"<="&$G$3)) | D8: =IF(A8="","",SUMIFS(Paradas!$F$5:$F$4004,Paradas!$B$5:$B$4004,$A8,Paradas!$A$5:$A$4004,">="&$E$3,Paradas!$A$5:$A$4004,"<="&$G$3)) | E8: =IF(A8="","",C8-D8) | F8: =IF(A8="","",COUNTIFS(Paradas!$B$5:$B$4004,$A8,Paradas!$A$5:$A$4004,">="&$E$3,Paradas!$A$5:$A$4004,"<="&$G$3)) | G8: =IF(A8="","",IF(B8=0,0,E8/B8)) | H8: =IF(A8="","",IF(C8=0,0,E8/C8))
A9: =IF(Equipamentos!A9="","",Equipamentos!A9) | B9: =IF(A9="","",COUNTIFS('Lançamentos Diários'!$B$5:$B$2004,$A9,'Lançamentos Diários'!$A$5:$A$2004,">="&$E$3,'Lançamentos Diários'!$A$5:$A$2004,"<="&$G$3)) | C9: =IF(A9="","",SUMIFS('Lançamentos Diários'!$J$5:$J$2004,'Lançamentos Diários'!$B$5:$B$2004,$A9,'Lançamentos Diários'!$A$5:$A$2004,">="&$E$3,'Lançamentos Diários'!$A$5:$A$2004,"<="&$G$3)) | D9: =IF(A9="","",SUMIFS(Paradas!$F$5:$F$4004,Paradas!$B$5:$B$4004,$A9,Paradas!$A$5:$A$4004,">="&$E$3,Paradas!$A$5:$A$4004,"<="&$G$3)) | E9: =IF(A9="","",C9-D9) | F9: =IF(A9="","",COUNTIFS(Paradas!$B$5:$B$4004,$A9,Paradas!$A$5:$A$4004,">="&$E$3,Paradas!$A$5:$A$4004,"<="&$G$3)) | G9: =IF(A9="","",IF(B9=0,0,E9/B9)) | H9: =IF(A9="","",IF(C9=0,0,E9/C9))
A10: =IF(Equipamentos!A10="","",Equipamentos!A10) | B10: =IF(A10="","",COUNTIFS('Lançamentos Diários'!$B$5:$B$2004,$A10,'Lançamentos Diários'!$A$5:$A$2004,">="&$E$3,'Lançamentos Diários'!$A$5:$A$2004,"<="&$G$3)) | C10: =IF(A10="","",SUMIFS('Lançamentos Diários'!$J$5:$J$2004,'Lançamentos Diários'!$B$5:$B$2004,$A10,'Lançamentos Diários'!$A$5:$A$2004,">="&$E$3,'Lançamentos Diários'!$A$5:$A$2004,"<="&$G$3)) | D10: =IF(A10="","",SUMIFS(Paradas!$F$5:$F$4004,Paradas!$B$5:$B$4004,$A10,Paradas!$A$5:$A$4004,">="&$E$3,Paradas!$A$5:$A$4004,"<="&$G$3)) | E10: =IF(A10="","",C10-D10) | F10: =IF(A10="","",COUNTIFS(Paradas!$B$5:$B$4004,$A10,Paradas!$A$5:$A$4004,">="&$E$3,Paradas!$A$5:$A$4004,"<="&$G$3)) | G10: =IF(A10="","",IF(B10=0,0,E10/B10)) | H10: =IF(A10="","",IF(C10=0,0,E10/C10))
A11: =IF(Equipamentos!A11="","",Equipamentos!A11) | B11: =IF(A11="","",COUNTIFS('Lançamentos Diários'!$B$5:$B$2004,$A11,'Lançamentos Diários'!$A$5:$A$2004,">="&$E$3,'Lançamentos Diários'!$A$5:$A$2004,"<="&$G$3)) | C11: =IF(A11="","",SUMIFS('Lançamentos Diários'!$J$5:$J$2004,'Lançamentos Diários'!$B$5:$B$2004,$A11,'Lançamentos Diários'!$A$5:$A$2004,">="&$E$3,'Lançamentos Diários'!$A$5:$A$2004,"<="&$G$3)) | D11: =IF(A11="","",SUMIFS(Paradas!$F$5:$F$4004,Paradas!$B$5:$B$4004,$A11,Paradas!$A$5:$A$4004,">="&$E$3,Paradas!$A$5:$A$4004,"<="&$G$3)) | E11: =IF(A11="","",C11-D11) | F11: =IF(A11="","",COUNTIFS(Paradas!$B$5:$B$4004,$A11,Paradas!$A$5:$A$4004,">="&$E$3,Paradas!$A$5:$A$4004,"<="&$G$3)) | G11: =IF(A11="","",IF(B11=0,0,E11/B11)) | H11: =IF(A11="","",IF(C11=0,0,E11/C11))
A12: TOTAL | B12: =SUM(B6:B11) | C12: =SUM(C6:C11) | D12: =SUM(D6:D11) | E12: =SUM(E6:E11) | F12: =SUM(F6:F11) | H12: =IF(C12=0,0,E12/C12)
A15: HORAS PARADAS POR MOTIVO NO MÊS
A16: Motivo | B16: =IF(Equipamentos!A6="","",Equipamentos!A6) | C16: =IF(Equipamentos!A7="","",Equipamentos!A7) | D16: =IF(Equipamentos!A8="","",Equipamentos!A8) | E16: =IF(Equipamentos!A9="","",Equipamentos!A9) | F16: =IF(Equipamentos!A10="","",Equipamentos!A10) | G16: =IF(Equipamentos!A11="","",Equipamentos!A11) | H16: Total
A17: =IF('Motivos de Parada'!A7="","",'Motivos de Parada'!A7) | B17: =IF(OR($A17="",B$16=""),"",SUMIFS(Paradas!$F$5:$F$4004,Paradas!$E$5:$E$4004,$A17,Paradas!$B$5:$B$4004,B$16,Paradas!$A$5:$A$4004,">="&$E$3,Paradas!$A$5:$A$4004,"<="&$G$3)) | C17: =IF(OR($A17="",C$16=""),"",SUMIFS(Paradas!$F$5:$F$4004,Paradas!$E$5:$E$4004,$A17,Paradas!$B$5:$B$4004,C$16,Paradas!$A$5:$A$4004,">="&$E$3,Paradas!$A$5:$A$4004,"<="&$G$3)) | D17: =IF(OR($A17="",D$16=""),"",SUMIFS(Paradas!$F$5:$F$4004,Paradas!$E$5:$E$4004,$A17,Paradas!$B$5:$B$4004,D$16,Paradas!$A$5:$A$4004,">="&$E$3,Paradas!$A$5:$A$4004,"<="&$G$3)) | E17: =IF(OR($A17="",E$16=""),"",SUMIFS(Paradas!$F$5:$F$4004,Paradas!$E$5:$E$4004,$A17,Paradas!$B$5:$B$4004,E$16,Paradas!$A$5:$A$4004,">="&$E$3,Paradas!$A$5:$A$4004,"<="&$G$3)) | F17: =IF(OR($A17="",F$16=""),"",SUMIFS(Paradas!$F$5:$F$4004,Paradas!$E$5:$E$4004,$A17,Paradas!$B$5:$B$4004,F$16,Paradas!$A$5:$A$4004,">="&$E$3,Paradas!$A$5:$A$4004,"<="&$G$3)) | G17: =IF(OR($A17="",G$16=""),"",SUMIFS(Paradas!$F$5:$F$4004,Paradas!$E$5:$E$4004,$A17,Paradas!$B$5:$B$4004,G$16,Paradas!$A$5:$A$4004,">="&$E$3,Paradas!$A$5:$A$4004,"<="&$G$3)) | H17: =IF($A17="","",SUM(B17:G17))
A18: =IF('Motivos de Parada'!A8="","",'Motivos de Parada'!A8) | B18: =IF(OR($A18="",B$16=""),"",SUMIFS(Paradas!$F$5:$F$4004,Paradas!$E$5:$E$4004,$A18,Paradas!$B$5:$B$4004,B$16,Paradas!$A$5:$A$4004,">="&$E$3,Paradas!$A$5:$A$4004,"<="&$G$3)) | C18: =IF(OR($A18="",C$16=""),"",SUMIFS(Paradas!$F$5:$F$4004,Paradas!$E$5:$E$4004,$A18,Paradas!$B$5:$B$4004,C$16,Paradas!$A$5:$A$4004,">="&$E$3,Paradas!$A$5:$A$4004,"<="&$G$3)) | D18: =IF(OR($A18="",D$16=""),"",SUMIFS(Paradas!$F$5:$F$4004,Paradas!$E$5:$E$4004,$A18,Paradas!$B$5:$B$4004,D$16,Paradas!$A$5:$A$4004,">="&$E$3,Paradas!$A$5:$A$4004,"<="&$G$3)) | E18: =IF(OR($A18="",E$16=""),"",SUMIFS(Paradas!$F$5:$F$4004,Paradas!$E$5:$E$4004,$A18,Paradas!$B$5:$B$4004,E$16,Paradas!$A$5:$A$4004,">="&$E$3,Paradas!$A$5:$A$4004,"<="&$G$3)) | F18: =IF(OR($A18="",F$16=""),"",SUMIFS(Paradas!$F$5:$F$4004,Paradas!$E$5:$E$4004,$A18,Paradas!$B$5:$B$4004,F$16,Paradas!$A$5:$A$4004,">="&$E$3,Paradas!$A$5:$A$4004,"<="&$G$3)) | G18: =IF(OR($A18="",G$16=""),"",SUMIFS(Paradas!$F$5:$F$4004,Paradas!$E$5:$E$4004,$A18,Paradas!$B$5:$B$4004,G$16,Paradas!$A$5:$A$4004,">="&$E$3,Paradas!$A$5:$A$4004,"<="&$G$3)) | H18: =IF($A18="","",SUM(B18:G18))
A19: =IF('Motivos de Parada'!A9="","",'Motivos de Parada'!A9) | B19: =IF(OR($A19="",B$16=""),"",SUMIFS(Paradas!$F$5:$F$4004,Paradas!$E$5:$E$4004,$A19,Paradas!$B$5:$B$4004,B$16,Paradas!$A$5:$A$4004,">="&$E$3,Paradas!$A$5:$A$4004,"<="&$G$3)) | C19: =IF(OR($A19="",C$16=""),"",SUMIFS(Paradas!$F$5:$F$4004,Paradas!$E$5:$E$4004,$A19,Paradas!$B$5:$B$4004,C$16,Paradas!$A$5:$A$4004,">="&$E$3,Paradas!$A$5:$A$4004,"<="&$G$3)) | D19: =IF(OR($A19="",D$16=""),"",SUMIFS(Paradas!$F$5:$F$4004,Paradas!$E$5:$E$4004,$A19,Paradas!$B$5:$B$4004,D$16,Paradas!$A$5:$A$4004,">="&$E$3,Paradas!$A$5:$A$4004,"<="&$G$3)) | E19: =IF(OR($A19="",E$16=""),"",SUMIFS(Paradas!$F$5:$F$4004,Paradas!$E$5:$E$4004,$A19,Paradas!$B$5:$B$4004,E$16,Paradas!$A$5:$A$4004,">="&$E$3,Paradas!$A$5:$A$4004,"<="&$G$3)) | F19: =IF(OR($A19="",F$16=""),"",SUMIFS(Paradas!$F$5:$F$4004,Paradas!$E$5:$E$4004,$A19,Paradas!$B$5:$B$4004,F$16,Paradas!$A$5:$A$4004,">="&$E$3,Paradas!$A$5:$A$4004,"<="&$G$3)) | G19: =IF(OR($A19="",G$16=""),"",SUMIFS(Paradas!$F$5:$F$4004,Paradas!$E$5:$E$4004,$A19,Paradas!$B$5:$B$4004,G$16,Paradas!$A$5:$A$4004,">="&$E$3,Paradas!$A$5:$A$4004,"<="&$G$3)) | H19: =IF($A19="","",SUM(B19:G19))
A20: =IF('Motivos de Parada'!A10="","",'Motivos de Parada'!A10) | B20: =IF(OR($A20="",B$16=""),"",SUMIFS(Paradas!$F$5:$F$4004,Paradas!$E$5:$E$4004,$A20,Paradas!$B$5:$B$4004,B$16,Paradas!$A$5:$A$4004,">="&$E$3,Paradas!$A$5:$A$4004,"<="&$G$3)) | C20: =IF(OR($A20="",C$16=""),"",SUMIFS(Paradas!$F$5:$F$4004,Paradas!$E$5:$E$4004,$A20,Paradas!$B$5:$B$4004,C$16,Paradas!$A$5:$A$4004,">="&$E$3,Paradas!$A$5:$A$4004,"<="&$G$3)) | D20: =IF(OR($A20="",D$16=""),"",SUMIFS(Paradas!$F$5:$F$4004,Paradas!$E$5:$E$4004,$A20,Paradas!$B$5:$B$4004,D$16,Paradas!$A$5:$A$4004,">="&$E$3,Paradas!$A$5:$A$4004,"<="&$G$3)) | E20: =IF(OR($A20="",E$16=""),"",SUMIFS(Paradas!$F$5:$F$4004,Paradas!$E$5:$E$4004,$A20,Paradas!$B$5:$B$4004,E$16,Paradas!$A$5:$A$4004,">="&$E$3,Paradas!$A$5:$A$4004,"<="&$G$3)) | F20: =IF(OR($A20="",F$16=""),"",SUMIFS(Paradas!$F$5:$F$4004,Paradas!$E$5:$E$4004,$A20,Paradas!$B$5:$B$4004,F$16,Paradas!$A$5:$A$4004,">="&$E$3,Paradas!$A$5:$A$4004,"<="&$G$3)) | G20: =IF(OR($A20="",G$16=""),"",SUMIFS(Paradas!$F$5:$F$4004,Paradas!$E$5:$E$4004,$A20,Paradas!$B$5:$B$4004,G$16,Paradas!$A$5:$A$4004,">="&$E$3,Paradas!$A$5:$A$4004,"<="&$G$3)) | H20: =IF($A20="","",SUM(B20:G20))
A21: =IF('Motivos de Parada'!A11="","",'Motivos de Parada'!A11) | B21: =IF(OR($A21="",B$16=""),"",SUMIFS(Paradas!$F$5:$F$4004,Paradas!$E$5:$E$4004,$A21,Paradas!$B$5:$B$4004,B$16,Paradas!$A$5:$A$4004,">="&$E$3,Paradas!$A$5:$A$4004,"<="&$G$3)) | C21: =IF(OR($A21="",C$16=""),"",SUMIFS(Paradas!$F$5:$F$4004,Paradas!$E$5:$E$4004,$A21,Paradas!$B$5:$B$4004,C$16,Paradas!$A$5:$A$4004,">="&$E$3,Paradas!$A$5:$A$4004,"<="&$G$3)) | D21: =IF(OR($A21="",D$16=""),"",SUMIFS(Paradas!$F$5:$F$4004,Paradas!$E$5:$E$4004,$A21,Paradas!$B$5:$B$4004,D$16,Paradas!$A$5:$A$4004,">="&$E$3,Paradas!$A$5:$A$4004,"<="&$G$3)) | E21: =IF(OR($A21="",E$16=""),"",SUMIFS(Paradas!$F$5:$F$4004,Paradas!$E$5:$E$4004,$A21,Paradas!$B$5:$B$4004,E$16,Paradas!$A$5:$A$4004,">="&$E$3,Paradas!$A$5:$A$4004,"<="&$G$3)) | F21: =IF(OR($A21="",F$16=""),"",SUMIFS(Paradas!$F$5:$F$4004,Paradas!$E$5:$E$4004,$A21,Paradas!$B$5:$B$4004,F$16,Paradas!$A$5:$A$4004,">="&$E$3,Paradas!$A$5:$A$4004,"<="&$G$3)) | G21: =IF(OR($A21="",G$16=""),"",SUMIFS(Paradas!$F$5:$F$4004,Paradas!$E$5:$E$4004,$A21,Paradas!$B$5:$B$4004,G$16,Paradas!$A$5:$A$4004,">="&$E$3,Paradas!$A$5:$A$4004,"<="&$G$3)) | H21: =IF($A21="","",SUM(B21:G21))
A22: =IF('Motivos de Parada'!A12="","",'Motivos de Parada'!A12) | B22: =IF(OR($A22="",B$16=""),"",SUMIFS(Paradas!$F$5:$F$4004,Paradas!$E$5:$E$4004,$A22,Paradas!$B$5:$B$4004,B$16,Paradas!$A$5:$A$4004,">="&$E$3,Paradas!$A$5:$A$4004,"<="&$G$3)) | C22: =IF(OR($A22="",C$16=""),"",SUMIFS(Paradas!$F$5:$F$4004,Paradas!$E$5:$E$4004,$A22,Paradas!$B$5:$B$4004,C$16,Paradas!$A$5:$A$4004,">="&$E$3,Paradas!$A$5:$A$4004,"<="&$G$3)) | D22: =IF(OR($A22="",D$16=""),"",SUMIFS(Paradas!$F$5:$F$4004,Paradas!$E$5:$E$4004,$A22,Paradas!$B$5:$B$4004,D$16,Paradas!$A$5:$A$4004,">="&$E$3,Paradas!$A$5:$A$4004,"<="&$G$3)) | E22: =IF(OR($A22="",E$16=""),"",SUMIFS(Paradas!$F$5:$F$4004,Paradas!$E$5:$E$4004,$A22,Paradas!$B$5:$B$4004,E$16,Paradas!$A$5:$A$4004,">="&$E$3,Paradas!$A$5:$A$4004,"<="&$G$3)) | F22: =IF(OR($A22="",F$16=""),"",SUMIFS(Paradas!$F$5:$F$4004,Paradas!$E$5:$E$4004,$A22,Paradas!$B$5:$B$4004,F$16,Paradas!$A$5:$A$4004,">="&$E$3,Paradas!$A$5:$A$4004,"<="&$G$3)) | G22: =IF(OR($A22="",G$16=""),"",SUMIFS(Paradas!$F$5:$F$4004,Paradas!$E$5:$E$4004,$A22,Paradas!$B$5:$B$4004,G$16,Paradas!$A$5:$A$4004,">="&$E$3,Paradas!$A$5:$A$4004,"<="&$G$3)) | H22: =IF($A22="","",SUM(B22:G22))
A23: =IF('Motivos de Parada'!A13="","",'Motivos de Parada'!A13) | B23: =IF(OR($A23="",B$16=""),"",SUMIFS(Paradas!$F$5:$F$4004,Paradas!$E$5:$E$4004,$A23,Paradas!$B$5:$B$4004,B$16,Paradas!$A$5:$A$4004,">="&$E$3,Paradas!$A$5:$A$4004,"<="&$G$3)) | C23: =IF(OR($A23="",C$16=""),"",SUMIFS(Paradas!$F$5:$F$4004,Paradas!$E$5:$E$4004,$A23,Paradas!$B$5:$B$4004,C$16,Paradas!$A$5:$A$4004,">="&$E$3,Paradas!$A$5:$A$4004,"<="&$G$3)) | D23: =IF(OR($A23="",D$16=""),"",SUMIFS(Paradas!$F$5:$F$4004,Paradas!$E$5:$E$4004,$A23,Paradas!$B$5:$B$4004,D$16,Paradas!$A$5:$A$4004,">="&$E$3,Paradas!$A$5:$A$4004,"<="&$G$3)) | E23: =IF(OR($A23="",E$16=""),"",SUMIFS(Paradas!$F$5:$F$4004,Paradas!$E$5:$E$4004,$A23,Paradas!$B$5:$B$4004,E$16,Paradas!$A$5:$A$4004,">="&$E$3,Paradas!$A$5:$A$4004,"<="&$G$3)) | F23: =IF(OR($A23="",F$16=""),"",SUMIFS(Paradas!$F$5:$F$4004,Paradas!$E$5:$E$4004,$A23,Paradas!$B$5:$B$4004,F$16,Paradas!$A$5:$A$4004,">="&$E$3,Paradas!$A$5:$A$4004,"<="&$G$3)) | G23: =IF(OR($A23="",G$16=""),"",SUMIFS(Paradas!$F$5:$F$4004,Paradas!$E$5:$E$4004,$A23,Paradas!$B$5:$B$4004,G$16,Paradas!$A$5:$A$4004,">="&$E$3,Paradas!$A$5:$A$4004,"<="&$G$3)) | H23: =IF($A23="","",SUM(B23:G23))
A24: =IF('Motivos de Parada'!A14="","",'Motivos de Parada'!A14) | B24: =IF(OR($A24="",B$16=""),"",SUMIFS(Paradas!$F$5:$F$4004,Paradas!$E$5:$E$4004,$A24,Paradas!$B$5:$B$4004,B$16,Paradas!$A$5:$A$4004,">="&$E$3,Paradas!$A$5:$A$4004,"<="&$G$3)) | C24: =IF(OR($A24="",C$16=""),"",SUMIFS(Paradas!$F$5:$F$4004,Paradas!$E$5:$E$4004,$A24,Paradas!$B$5:$B$4004,C$16,Paradas!$A$5:$A$4004,">="&$E$3,Paradas!$A$5:$A$4004,"<="&$G$3)) | D24: =IF(OR($A24="",D$16=""),"",SUMIFS(Paradas!$F$5:$F$4004,Paradas!$E$5:$E$4004,$A24,Paradas!$B$5:$B$4004,D$16,Paradas!$A$5:$A$4004,">="&$E$3,Paradas!$A$5:$A$4004,"<="&$G$3)) | E24: =IF(OR($A24="",E$16=""),"",SUMIFS(Paradas!$F$5:$F$4004,Paradas!$E$5:$E$4004,$A24,Paradas!$B$5:$B$4004,E$16,Paradas!$A$5:$A$4004,">="&$E$3,Paradas!$A$5:$A$4004,"<="&$G$3)) | F24: =IF(OR($A24="",F$16=""),"",SUMIFS(Paradas!$F$5:$F$4004,Paradas!$E$5:$E$4004,$A24,Paradas!$B$5:$B$4004,F$16,Paradas!$A$5:$A$4004,">="&$E$3,Paradas!$A$5:$A$4004,"<="&$G$3)) | G24: =IF(OR($A24="",G$16=""),"",SUMIFS(Paradas!$F$5:$F$4004,Paradas!$E$5:$E$4004,$A24,Paradas!$B$5:$B$4004,G$16,Paradas!$A$5:$A$4004,">="&$E$3,Paradas!$A$5:$A$4004,"<="&$G$3)) | H24: =IF($A24="","",SUM(B24:G24))
A25: =IF('Motivos de Parada'!A15="","",'Motivos de Parada'!A15) | B25: =IF(OR($A25="",B$16=""),"",SUMIFS(Paradas!$F$5:$F$4004,Paradas!$E$5:$E$4004,$A25,Paradas!$B$5:$B$4004,B$16,Paradas!$A$5:$A$4004,">="&$E$3,Paradas!$A$5:$A$4004,"<="&$G$3)) | C25: =IF(OR($A25="",C$16=""),"",SUMIFS(Paradas!$F$5:$F$4004,Paradas!$E$5:$E$4004,$A25,Paradas!$B$5:$B$4004,C$16,Paradas!$A$5:$A$4004,">="&$E$3,Paradas!$A$5:$A$4004,"<="&$G$3)) | D25: =IF(OR($A25="",D$16=""),"",SUMIFS(Paradas!$F$5:$F$4004,Paradas!$E$5:$E$4004,$A25,Paradas!$B$5:$B$4004,D$16,Paradas!$A$5:$A$4004,">="&$E$3,Paradas!$A$5:$A$4004,"<="&$G$3)) | E25: =IF(OR($A25="",E$16=""),"",SUMIFS(Paradas!$F$5:$F$4004,Paradas!$E$5:$E$4004,$A25,Paradas!$B$5:$B$4004,E$16,Paradas!$A$5:$A$4004,">="&$E$3,Paradas!$A$5:$A$4004,"<="&$G$3)) | F25: =IF(OR($A25="",F$16=""),"",SUMIFS(Paradas!$F$5:$F$4004,Paradas!$E$5:$E$4004,$A25,Paradas!$B$5:$B$4004,F$16,Paradas!$A$5:$A$4004,">="&$E$3,Paradas!$A$5:$A$4004,"<="&$G$3)) | G25: =IF(OR($A25="",G$16=""),"",SUMIFS(Paradas!$F$5:$F$4004,Paradas!$E$5:$E$4004,$A25,Paradas!$B$5:$B$4004,G$16,Paradas!$A$5:$A$4004,">="&$E$3,Paradas!$A$5:$A$4004,"<="&$G$3)) | H25: =IF($A25="","",SUM(B25:G25))
A26: =IF('Motivos de Parada'!A16="","",'Motivos de Parada'!A16) | B26: =IF(OR($A26="",B$16=""),"",SUMIFS(Paradas!$F$5:$F$4004,Paradas!$E$5:$E$4004,$A26,Paradas!$B$5:$B$4004,B$16,Paradas!$A$5:$A$4004,">="&$E$3,Paradas!$A$5:$A$4004,"<="&$G$3)) | C26: =IF(OR($A26="",C$16=""),"",SUMIFS(Paradas!$F$5:$F$4004,Paradas!$E$5:$E$4004,$A26,Paradas!$B$5:$B$4004,C$16,Paradas!$A$5:$A$4004,">="&$E$3,Paradas!$A$5:$A$4004,"<="&$G$3)) | D26: =IF(OR($A26="",D$16=""),"",SUMIFS(Paradas!$F$5:$F$4004,Paradas!$E$5:$E$4004,$A26,Paradas!$B$5:$B$4004,D$16,Paradas!$A$5:$A$4004,">="&$E$3,Paradas!$A$5:$A$4004,"<="&$G$3)) | E26: =IF(OR($A26="",E$16=""),"",SUMIFS(Paradas!$F$5:$F$4004,Paradas!$E$5:$E$4004,$A26,Paradas!$B$5:$B$4004,E$16,Paradas!$A$5:$A$4004,">="&$E$3,Paradas!$A$5:$A$4004,"<="&$G$3)) | F26: =IF(OR($A26="",F$16=""),"",SUMIFS(Paradas!$F$5:$F$4004,Paradas!$E$5:$E$4004,$A26,Paradas!$B$5:$B$4004,F$16,Paradas!$A$5:$A$4004,">="&$E$3,Paradas!$A$5:$A$4004,"<="&$G$3)) | G26: =IF(OR($A26="",G$16=""),"",SUMIFS(Paradas!$F$5:$F$4004,Paradas!$E$5:$E$4004,$A26,Paradas!$B$5:$B$4004,G$16,Paradas!$A$5:$A$4004,">="&$E$3,Paradas!$A$5:$A$4004,"<="&$G$3)) | H26: =IF($A26="","",SUM(B26:G26))
A27: =IF('Motivos de Parada'!A17="","",'Motivos de Parada'!A17) | B27: =IF(OR($A27="",B$16=""),"",SUMIFS(Paradas!$F$5:$F$4004,Paradas!$E$5:$E$4004,$A27,Paradas!$B$5:$B$4004,B$16,Paradas!$A$5:$A$4004,">="&$E$3,Paradas!$A$5:$A$4004,"<="&$G$3)) | C27: =IF(OR($A27="",C$16=""),"",SUMIFS(Paradas!$F$5:$F$4004,Paradas!$E$5:$E$4004,$A27,Paradas!$B$5:$B$4004,C$16,Paradas!$A$5:$A$4004,">="&$E$3,Paradas!$A$5:$A$4004,"<="&$G$3)) | D27: =IF(OR($A27="",D$16=""),"",SUMIFS(Paradas!$F$5:$F$4004,Paradas!$E$5:$E$4004,$A27,Paradas!$B$5:$B$4004,D$16,Paradas!$A$5:$A$4004,">="&$E$3,Paradas!$A$5:$A$4004,"<="&$G$3)) | E27: =IF(OR($A27="",E$16=""),"",SUMIFS(Paradas!$F$5:$F$4004,Paradas!$E$5:$E$4004,$A27,Paradas!$B$5:$B$4004,E$16,Paradas!$A$5:$A$4004,">="&$E$3,Paradas!$A$5:$A$4004,"<="&$G$3)) | F27: =IF(OR($A27="",F$16=""),"",SUMIFS(Paradas!$F$5:$F$4004,Paradas!$E$5:$E$4004,$A27,Paradas!$B$5:$B$4004,F$16,Paradas!$A$5:$A$4004,">="&$E$3,Paradas!$A$5:$A$4004,"<="&$G$3)) | G27: =IF(OR($A27="",G$16=""),"",SUMIFS(Paradas!$F$5:$F$4004,Paradas!$E$5:$E$4004,$A27,Paradas!$B$5:$B$4004,G$16,Paradas!$A$5:$A$4004,">="&$E$3,Paradas!$A$5:$A$4004,"<="&$G$3)) | H27: =IF($A27="","",SUM(B27:G27))
A28: =IF('Motivos de Parada'!A18="","",'Motivos de Parada'!A18) | B28: =IF(OR($A28="",B$16=""),"",SUMIFS(Paradas!$F$5:$F$4004,Paradas!$E$5:$E$4004,$A28,Paradas!$B$5:$B$4004,B$16,Paradas!$A$5:$A$4004,">="&$E$3,Paradas!$A$5:$A$4004,"<="&$G$3)) | C28: =IF(OR($A28="",C$16=""),"",SUMIFS(Paradas!$F$5:$F$4004,Paradas!$E$5:$E$4004,$A28,Paradas!$B$5:$B$4004,C$16,Paradas!$A$5:$A$4004,">="&$E$3,Paradas!$A$5:$A$4004,"<="&$G$3)) | D28: =IF(OR($A28="",D$16=""),"",SUMIFS(Paradas!$F$5:$F$4004,Paradas!$E$5:$E$4004,$A28,Paradas!$B$5:$B$4004,D$16,Paradas!$A$5:$A$4004,">="&$E$3,Paradas!$A$5:$A$4004,"<="&$G$3)) | E28: =IF(OR($A28="",E$16=""),"",SUMIFS(Paradas!$F$5:$F$4004,Paradas!$E$5:$E$4004,$A28,Paradas!$B$5:$B$4004,E$16,Paradas!$A$5:$A$4004,">="&$E$3,Paradas!$A$5:$A$4004,"<="&$G$3)) | F28: =IF(OR($A28="",F$16=""),"",SUMIFS(Paradas!$F$5:$F$4004,Paradas!$E$5:$E$4004,$A28,Paradas!$B$5:$B$4004,F$16,Paradas!$A$5:$A$4004,">="&$E$3,Paradas!$A$5:$A$4004,"<="&$G$3)) | G28: =IF(OR($A28="",G$16=""),"",SUMIFS(Paradas!$F$5:$F$4004,Paradas!$E$5:$E$4004,$A28,Paradas!$B$5:$B$4004,G$16,Paradas!$A$5:$A$4004,">="&$E$3,Paradas!$A$5:$A$4004,"<="&$G$3)) | H28: =IF($A28="","",SUM(B28:G28))
... A36: =IF('Motivos de Parada'!A26="","",'Motivos de Parada'!A26) | B36: =IF(OR($A36="",B$16=""),"",SUMIFS(Paradas!$F$5:$F$4004,Paradas!$E$5:$E$4004,$A36,Paradas!$B$5:$B$4004,B$16,Paradas!$A$5:$A$4004,">="&$E$3,Paradas!$A$5:$A$4004,"<="&$G$3)) | C36: =IF(OR($A36="",C$16=""),"",SUMIFS(Paradas!$F$5:$F$4004,Paradas!$E$5:$E$4004,$A36,Paradas!$B$5:$B$4004,C$16,Paradas!$A$5:$A$4004,">="&$E$3,Paradas!$A$5:$A$4004,"<="&$G$3)) | D36: =IF(OR($A36="",D$16=""),"",SUMIFS(Paradas!$F$5:$F$4004,Paradas!$E$5:$E$4004,$A36,Paradas!$B$5:$B$4004,D$16,Paradas!$A$5:$A$4004,">="&$E$3,Paradas!$A$5:$A$4004,"<="&$G$3)) | E36: =IF(OR($A36="",E$16=""),"",SUMIFS(Paradas!$F$5:$F$4004,Paradas!$E$5:$E$4004,$A36,Paradas!$B$5:$B$4004,E$16,Paradas!$A$5:$A$4004,">="&$E$3,Paradas!$A$5:$A$4004,"<="&$G$3)) | F36: =IF(OR($A36="",F$16=""),"",SUMIFS(Paradas!$F$5:$F$4004,Paradas!$E$5:$E$4004,$A36,Paradas!$B$5:$B$4004,F$16,Paradas!$A$5:$A$4004,">="&$E$3,Paradas!$A$5:$A$4004,"<="&$G$3)) | G36: =IF(OR($A36="",G$16=""),"",SUMIFS(Paradas!$F$5:$F$4004,Paradas!$E$5:$E$4004,$A36,Paradas!$B$5:$B$4004,G$16,Paradas!$A$5:$A$4004,">="&$E$3,Paradas!$A$5:$A$4004,"<="&$G$3)) | H36: =IF($A36="","",SUM(B36:G36))
A37: TOTAL | B37: =SUM(B17:B36) | C37: =SUM(C17:C36) | D37: =SUM(D17:D36) | E37: =SUM(E17:E36) | F37: =SUM(F17:F36) | G37: =SUM(G17:G36) | H37: =SUM(H17:H36)

Sheet Março
B1: RESUMO MENSAL — MARÇO
A3: Mês de referência: | B3: =DATE('Resumo Anual'!$B$3,3,1) | D3: De: | E3: =DATE(YEAR(B3),MONTH(B3),1) | F3: até: | G3: =EOMONTH(B3,0)
A5: Equipamento | B5: Dias lançados | C5: Horas totais | D5: Horas paradas | E5: Horas efetivas trabalhadas | F5: Nº de paradas | G5: Média efetiva por dia | H5: % do tempo trabalhando
A6: =IF(Equipamentos!A6="","",Equipamentos!A6) | B6: =IF(A6="","",COUNTIFS('Lançamentos Diários'!$B$5:$B$2004,$A6,'Lançamentos Diários'!$A$5:$A$2004,">="&$E$3,'Lançamentos Diários'!$A$5:$A$2004,"<="&$G$3)) | C6: =IF(A6="","",SUMIFS('Lançamentos Diários'!$J$5:$J$2004,'Lançamentos Diários'!$B$5:$B$2004,$A6,'Lançamentos Diários'!$A$5:$A$2004,">="&$E$3,'Lançamentos Diários'!$A$5:$A$2004,"<="&$G$3)) | D6: =IF(A6="","",SUMIFS(Paradas!$F$5:$F$4004,Paradas!$B$5:$B$4004,$A6,Paradas!$A$5:$A$4004,">="&$E$3,Paradas!$A$5:$A$4004,"<="&$G$3)) | E6: =IF(A6="","",C6-D6) | F6: =IF(A6="","",COUNTIFS(Paradas!$B$5:$B$4004,$A6,Paradas!$A$5:$A$4004,">="&$E$3,Paradas!$A$5:$A$4004,"<="&$G$3)) | G6: =IF(A6="","",IF(B6=0,0,E6/B6)) | H6: =IF(A6="","",IF(C6=0,0,E6/C6))
A7: =IF(Equipamentos!A7="","",Equipamentos!A7) | B7: =IF(A7="","",COUNTIFS('Lançamentos Diários'!$B$5:$B$2004,$A7,'Lançamentos Diários'!$A$5:$A$2004,">="&$E$3,'Lançamentos Diários'!$A$5:$A$2004,"<="&$G$3)) | C7: =IF(A7="","",SUMIFS('Lançamentos Diários'!$J$5:$J$2004,'Lançamentos Diários'!$B$5:$B$2004,$A7,'Lançamentos Diários'!$A$5:$A$2004,">="&$E$3,'Lançamentos Diários'!$A$5:$A$2004,"<="&$G$3)) | D7: =IF(A7="","",SUMIFS(Paradas!$F$5:$F$4004,Paradas!$B$5:$B$4004,$A7,Paradas!$A$5:$A$4004,">="&$E$3,Paradas!$A$5:$A$4004,"<="&$G$3)) | E7: =IF(A7="","",C7-D7) | F7: =IF(A7="","",COUNTIFS(Paradas!$B$5:$B$4004,$A7,Paradas!$A$5:$A$4004,">="&$E$3,Paradas!$A$5:$A$4004,"<="&$G$3)) | G7: =IF(A7="","",IF(B7=0,0,E7/B7)) | H7: =IF(A7="","",IF(C7=0,0,E7/C7))
A8: =IF(Equipamentos!A8="","",Equipamentos!A8) | B8: =IF(A8="","",COUNTIFS('Lançamentos Diários'!$B$5:$B$2004,$A8,'Lançamentos Diários'!$A$5:$A$2004,">="&$E$3,'Lançamentos Diários'!$A$5:$A$2004,"<="&$G$3)) | C8: =IF(A8="","",SUMIFS('Lançamentos Diários'!$J$5:$J$2004,'Lançamentos Diários'!$B$5:$B$2004,$A8,'Lançamentos Diários'!$A$5:$A$2004,">="&$E$3,'Lançamentos Diários'!$A$5:$A$2004,"<="&$G$3)) | D8: =IF(A8="","",SUMIFS(Paradas!$F$5:$F$4004,Paradas!$B$5:$B$4004,$A8,Paradas!$A$5:$A$4004,">="&$E$3,Paradas!$A$5:$A$4004,"<="&$G$3)) | E8: =IF(A8="","",C8-D8) | F8: =IF(A8="","",COUNTIFS(Paradas!$B$5:$B$4004,$A8,Paradas!$A$5:$A$4004,">="&$E$3,Paradas!$A$5:$A$4004,"<="&$G$3)) | G8: =IF(A8="","",IF(B8=0,0,E8/B8)) | H8: =IF(A8="","",IF(C8=0,0,E8/C8))
A9: =IF(Equipamentos!A9="","",Equipamentos!A9) | B9: =IF(A9="","",COUNTIFS('Lançamentos Diários'!$B$5:$B$2004,$A9,'Lançamentos Diários'!$A$5:$A$2004,">="&$E$3,'Lançamentos Diários'!$A$5:$A$2004,"<="&$G$3)) | C9: =IF(A9="","",SUMIFS('Lançamentos Diários'!$J$5:$J$2004,'Lançamentos Diários'!$B$5:$B$2004,$A9,'Lançamentos Diários'!$A$5:$A$2004,">="&$E$3,'Lançamentos Diários'!$A$5:$A$2004,"<="&$G$3)) | D9: =IF(A9="","",SUMIFS(Paradas!$F$5:$F$4004,Paradas!$B$5:$B$4004,$A9,Paradas!$A$5:$A$4004,">="&$E$3,Paradas!$A$5:$A$4004,"<="&$G$3)) | E9: =IF(A9="","",C9-D9) | F9: =IF(A9="","",COUNTIFS(Paradas!$B$5:$B$4004,$A9,Paradas!$A$5:$A$4004,">="&$E$3,Paradas!$A$5:$A$4004,"<="&$G$3)) | G9: =IF(A9="","",IF(B9=0,0,E9/B9)) | H9: =IF(A9="","",IF(C9=0,0,E9/C9))
A10: =IF(Equipamentos!A10="","",Equipamentos!A10) | B10: =IF(A10="","",COUNTIFS('Lançamentos Diários'!$B$5:$B$2004,$A10,'Lançamentos Diários'!$A$5:$A$2004,">="&$E$3,'Lançamentos Diários'!$A$5:$A$2004,"<="&$G$3)) | C10: =IF(A10="","",SUMIFS('Lançamentos Diários'!$J$5:$J$2004,'Lançamentos Diários'!$B$5:$B$2004,$A10,'Lançamentos Diários'!$A$5:$A$2004,">="&$E$3,'Lançamentos Diários'!$A$5:$A$2004,"<="&$G$3)) | D10: =IF(A10="","",SUMIFS(Paradas!$F$5:$F$4004,Paradas!$B$5:$B$4004,$A10,Paradas!$A$5:$A$4004,">="&$E$3,Paradas!$A$5:$A$4004,"<="&$G$3)) | E10: =IF(A10="","",C10-D10) | F10: =IF(A10="","",COUNTIFS(Paradas!$B$5:$B$4004,$A10,Paradas!$A$5:$A$4004,">="&$E$3,Paradas!$A$5:$A$4004,"<="&$G$3)) | G10: =IF(A10="","",IF(B10=0,0,E10/B10)) | H10: =IF(A10="","",IF(C10=0,0,E10/C10))
A11: =IF(Equipamentos!A11="","",Equipamentos!A11) | B11: =IF(A11="","",COUNTIFS('Lançamentos Diários'!$B$5:$B$2004,$A11,'Lançamentos Diários'!$A$5:$A$2004,">="&$E$3,'Lançamentos Diários'!$A$5:$A$2004,"<="&$G$3)) | C11: =IF(A11="","",SUMIFS('Lançamentos Diários'!$J$5:$J$2004,'Lançamentos Diários'!$B$5:$B$2004,$A11,'Lançamentos Diários'!$A$5:$A$2004,">="&$E$3,'Lançamentos Diários'!$A$5:$A$2004,"<="&$G$3)) | D11: =IF(A11="","",SUMIFS(Paradas!$F$5:$F$4004,Paradas!$B$5:$B$4004,$A11,Paradas!$A$5:$A$4004,">="&$E$3,Paradas!$A$5:$A$4004,"<="&$G$3)) | E11: =IF(A11="","",C11-D11) | F11: =IF(A11="","",COUNTIFS(Paradas!$B$5:$B$4004,$A11,Paradas!$A$5:$A$4004,">="&$E$3,Paradas!$A$5:$A$4004,"<="&$G$3)) | G11: =IF(A11="","",IF(B11=0,0,E11/B11)) | H11: =IF(A11="","",IF(C11=0,0,E11/C11))
A12: TOTAL | B12: =SUM(B6:B11) | C12: =SUM(C6:C11) | D12: =SUM(D6:D11) | E12: =SUM(E6:E11) | F12: =SUM(F6:F11) | H12: =IF(C12=0,0,E12/C12)
A15: HORAS PARADAS POR MOTIVO NO MÊS
A16: Motivo | B16: =IF(Equipamentos!A6="","",Equipamentos!A6) | C16: =IF(Equipamentos!A7="","",Equipamentos!A7) | D16: =IF(Equipamentos!A8="","",Equipamentos!A8) | E16: =IF(Equipamentos!A9="","",Equipamentos!A9) | F16: =IF(Equipamentos!A10="","",Equipamentos!A10) | G16: =IF(Equipamentos!A11="","",Equipamentos!A11) | H16: Total
A17: =IF('Motivos de Parada'!A7="","",'Motivos de Parada'!A7) | B17: =IF(OR($A17="",B$16=""),"",SUMIFS(Paradas!$F$5:$F$4004,Paradas!$E$5:$E$4004,$A17,Paradas!$B$5:$B$4004,B$16,Paradas!$A$5:$A$4004,">="&$E$3,Paradas!$A$5:$A$4004,"<="&$G$3)) | C17: =IF(OR($A17="",C$16=""),"",SUMIFS(Paradas!$F$5:$F$4004,Paradas!$E$5:$E$4004,$A17,Paradas!$B$5:$B$4004,C$16,Paradas!$A$5:$A$4004,">="&$E$3,Paradas!$A$5:$A$4004,"<="&$G$3)) | D17: =IF(OR($A17="",D$16=""),"",SUMIFS(Paradas!$F$5:$F$4004,Paradas!$E$5:$E$4004,$A17,Paradas!$B$5:$B$4004,D$16,Paradas!$A$5:$A$4004,">="&$E$3,Paradas!$A$5:$A$4004,"<="&$G$3)) | E17: =IF(OR($A17="",E$16=""),"",SUMIFS(Paradas!$F$5:$F$4004,Paradas!$E$5:$E$4004,$A17,Paradas!$B$5:$B$4004,E$16,Paradas!$A$5:$A$4004,">="&$E$3,Paradas!$A$5:$A$4004,"<="&$G$3)) | F17: =IF(OR($A17="",F$16=""),"",SUMIFS(Paradas!$F$5:$F$4004,Paradas!$E$5:$E$4004,$A17,Paradas!$B$5:$B$4004,F$16,Paradas!$A$5:$A$4004,">="&$E$3,Paradas!$A$5:$A$4004,"<="&$G$3)) | G17: =IF(OR($A17="",G$16=""),"",SUMIFS(Paradas!$F$5:$F$4004,Paradas!$E$5:$E$4004,$A17,Paradas!$B$5:$B$4004,G$16,Paradas!$A$5:$A$4004,">="&$E$3,Paradas!$A$5:$A$4004,"<="&$G$3)) | H17: =IF($A17="","",SUM(B17:G17))
A18: =IF('Motivos de Parada'!A8="","",'Motivos de Parada'!A8) | B18: =IF(OR($A18="",B$16=""),"",SUMIFS(Paradas!$F$5:$F$4004,Paradas!$E$5:$E$4004,$A18,Paradas!$B$5:$B$4004,B$16,Paradas!$A$5:$A$4004,">="&$E$3,Paradas!$A$5:$A$4004,"<="&$G$3)) | C18: =IF(OR($A18="",C$16=""),"",SUMIFS(Paradas!$F$5:$F$4004,Paradas!$E$5:$E$4004,$A18,Paradas!$B$5:$B$4004,C$16,Paradas!$A$5:$A$4004,">="&$E$3,Paradas!$A$5:$A$4004,"<="&$G$3)) | D18: =IF(OR($A18="",D$16=""),"",SUMIFS(Paradas!$F$5:$F$4004,Paradas!$E$5:$E$4004,$A18,Paradas!$B$5:$B$4004,D$16,Paradas!$A$5:$A$4004,">="&$E$3,Paradas!$A$5:$A$4004,"<="&$G$3)) | E18: =IF(OR($A18="",E$16=""),"",SUMIFS(Paradas!$F$5:$F$4004,Paradas!$E$5:$E$4004,$A18,Paradas!$B$5:$B$4004,E$16,Paradas!$A$5:$A$4004,">="&$E$3,Paradas!$A$5:$A$4004,"<="&$G$3)) | F18: =IF(OR($A18="",F$16=""),"",SUMIFS(Paradas!$F$5:$F$4004,Paradas!$E$5:$E$4004,$A18,Paradas!$B$5:$B$4004,F$16,Paradas!$A$5:$A$4004,">="&$E$3,Paradas!$A$5:$A$4004,"<="&$G$3)) | G18: =IF(OR($A18="",G$16=""),"",SUMIFS(Paradas!$F$5:$F$4004,Paradas!$E$5:$E$4004,$A18,Paradas!$B$5:$B$4004,G$16,Paradas!$A$5:$A$4004,">="&$E$3,Paradas!$A$5:$A$4004,"<="&$G$3)) | H18: =IF($A18="","",SUM(B18:G18))
